Workbook
Name \a: #REF!
Name \b: #REF!
Name \c: #REF!
Name \g: #REF!
Name \N: #REF!
Name \o: #REF!
Name \P: #REF!
Name \P: #REF!
Name \P: #REF!
Name \P: #REF!
Name \r: #N/A
Name \s: #N/A
Name \x: #REF!
Name \y: #REF!
Name \z: #REF!
Name ___________________an1: [0]!is1b,[0]!is1c,[0]!STATS2,[0]!STATS3
Name ___________________an1: [0]!is1b,[0]!is1c,[0]!STATS2,[0]!STATS3
Name ___________________an1: [0]!is1b,[0]!is1c,[0]!STATS2,[0]!STATS3
Name __________________an1: [0]!is1b,[0]!is1c,[0]!STATS2,[0]!STATS3
Name __________________an1: [0]!is1b,[0]!is1c,[0]!STATS2,[0]!STATS3
Name __________________an1: [0]!is1b,[0]!is1c,[0]!STATS2,[0]!STATS3
Name __________________df1: {#N/A,#N/A,FALSE,"Calc";#N/A,#N/A,FALSE,"Sensitivity";#N/A,#N/A,FALSE,"LT Earn.Dil.";#N/A,#N/A,FALSE,"Dil. AVP"}
Name __________________df1: {#N/A,#N/A,FALSE,"Calc";#N/A,#N/A,FALSE,"Sensitivity";#N/A,#N/A,FALSE,"LT Earn.Dil.";#N/A,#N/A,FALSE,"Dil. AVP"}
Name __________________df1: {#N/A,#N/A,FALSE,"Calc";#N/A,#N/A,FALSE,"Sensitivity";#N/A,#N/A,FALSE,"LT Earn.Dil.";#N/A,#N/A,FALSE,"Dil. AVP"}
Name __________________df2: {#N/A,#N/A,FALSE,"Calc";#N/A,#N/A,FALSE,"Sensitivity";#N/A,#N/A,FALSE,"LT Earn.Dil.";#N/A,#N/A,FALSE,"Dil. AVP"}
Name __________________df2: {#N/A,#N/A,FALSE,"Calc";#N/A,#N/A,FALSE,"Sensitivity";#N/A,#N/A,FALSE,"LT Earn.Dil.";#N/A,#N/A,FALSE,"Dil. AVP"}
Name __________________df2: {#N/A,#N/A,FALSE,"Calc";#N/A,#N/A,FALSE,"Sensitivity";#N/A,#N/A,FALSE,"LT Earn.Dil.";#N/A,#N/A,FALSE,"Dil. AVP"}
Name __________________hd1: {#N/A,#N/A,FALSE,"Calc";#N/A,#N/A,FALSE,"Sensitivity";#N/A,#N/A,FALSE,"LT Earn.Dil.";#N/A,#N/A,FALSE,"Dil. AVP"}
Name __________________hd1: {#N/A,#N/A,FALSE,"Calc";#N/A,#N/A,FALSE,"Sensitivity";#N/A,#N/A,FALSE,"LT Earn.Dil.";#N/A,#N/A,FALSE,"Dil. AVP"}
Name __________________hd1: {#N/A,#N/A,FALSE,"Calc";#N/A,#N/A,FALSE,"Sensitivity";#N/A,#N/A,FALSE,"LT Earn.Dil.";#N/A,#N/A,FALSE,"Dil. AVP"}
Name __________________hd2: {#N/A,#N/A,FALSE,"Calc";#N/A,#N/A,FALSE,"Sensitivity";#N/A,#N/A,FALSE,"LT Earn.Dil.";#N/A,#N/A,FALSE,"Dil. AVP"}
Name __________________hd2: {#N/A,#N/A,FALSE,"Calc";#N/A,#N/A,FALSE,"Sensitivity";#N/A,#N/A,FALSE,"LT Earn.Dil.";#N/A,#N/A,FALSE,"Dil. AVP"}
Name __________________hd2: {#N/A,#N/A,FALSE,"Calc";#N/A,#N/A,FALSE,"Sensitivity";#N/A,#N/A,FALSE,"LT Earn.Dil.";#N/A,#N/A,FALSE,"Dil. AVP"}
Name __________________P1: [0]!_________________P1
Name __________________P1: [0]!_________________P1
Name __________________P1: [0]!_________________P1
Name _________________an1: [0]!is1b,[0]!is1c,[0]!STATS2,[0]!STATS3
Name _________________an1: [0]!is1b,[0]!is1c,[0]!STATS2,[0]!STATS3
Name _________________an1: [0]!is1b,[0]!is1c,[0]!STATS2,[0]!STATS3
Name _________________df1: {#N/A,#N/A,FALSE,"Calc";#N/A,#N/A,FALSE,"Sensitivity";#N/A,#N/A,FALSE,"LT Earn.Dil.";#N/A,#N/A,FALSE,"Dil. AVP"}
Name _________________df1: {#N/A,#N/A,FALSE,"Calc";#N/A,#N/A,FALSE,"Sensitivity";#N/A,#N/A,FALSE,"LT Earn.Dil.";#N/A,#N/A,FALSE,"Dil. AVP"}
Name _________________df1: {#N/A,#N/A,FALSE,"Calc";#N/A,#N/A,FALSE,"Sensitivity";#N/A,#N/A,FALSE,"LT Earn.Dil.";#N/A,#N/A,FALSE,"Dil. AVP"}
Name _________________df2: {#N/A,#N/A,FALSE,"Calc";#N/A,#N/A,FALSE,"Sensitivity";#N/A,#N/A,FALSE,"LT Earn.Dil.";#N/A,#N/A,FALSE,"Dil. AVP"}
Name _________________df2: {#N/A,#N/A,FALSE,"Calc";#N/A,#N/A,FALSE,"Sensitivity";#N/A,#N/A,FALSE,"LT Earn.Dil.";#N/A,#N/A,FALSE,"Dil. AVP"}
Name _________________df2: {#N/A,#N/A,FALSE,"Calc";#N/A,#N/A,FALSE,"Sensitivity";#N/A,#N/A,FALSE,"LT Earn.Dil.";#N/A,#N/A,FALSE,"Dil. AVP"}
Name _________________hd1: {#N/A,#N/A,FALSE,"Calc";#N/A,#N/A,FALSE,"Sensitivity";#N/A,#N/A,FALSE,"LT Earn.Dil.";#N/A,#N/A,FALSE,"Dil. AVP"}
Name _________________hd1: {#N/A,#N/A,FALSE,"Calc";#N/A,#N/A,FALSE,"Sensitivity";#N/A,#N/A,FALSE,"LT Earn.Dil.";#N/A,#N/A,FALSE,"Dil. AVP"}
Name _________________hd1: {#N/A,#N/A,FALSE,"Calc";#N/A,#N/A,FALSE,"Sensitivity";#N/A,#N/A,FALSE,"LT Earn.Dil.";#N/A,#N/A,FALSE,"Dil. AVP"}
Name _________________hd2: {#N/A,#N/A,FALSE,"Calc";#N/A,#N/A,FALSE,"Sensitivity";#N/A,#N/A,FALSE,"LT Earn.Dil.";#N/A,#N/A,FALSE,"Dil. AVP"}
Name _________________hd2: {#N/A,#N/A,FALSE,"Calc";#N/A,#N/A,FALSE,"Sensitivity";#N/A,#N/A,FALSE,"LT Earn.Dil.";#N/A,#N/A,FALSE,"Dil. AVP"}
Name _________________hd2: {#N/A,#N/A,FALSE,"Calc";#N/A,#N/A,FALSE,"Sensitivity";#N/A,#N/A,FALSE,"LT Earn.Dil.";#N/A,#N/A,FALSE,"Dil. AVP"}
Name _________________P1: #N/A
Name ________________df1: {#N/A,#N/A,FALSE,"Calc";#N/A,#N/A,FALSE,"Sensitivity";#N/A,#N/A,FALSE,"LT Earn.Dil.";#N/A,#N/A,FALSE,"Dil. AVP"}
Name ________________df1: {#N/A,#N/A,FALSE,"Calc";#N/A,#N/A,FALSE,"Sensitivity";#N/A,#N/A,FALSE,"LT Earn.Dil.";#N/A,#N/A,FALSE,"Dil. AVP"}
Name ________________df1: {#N/A,#N/A,FALSE,"Calc";#N/A,#N/A,FALSE,"Sensitivity";#N/A,#N/A,FALSE,"LT Earn.Dil.";#N/A,#N/A,FALSE,"Dil. AVP"}
Name ________________df2: {#N/A,#N/A,FALSE,"Calc";#N/A,#N/A,FALSE,"Sensitivity";#N/A,#N/A,FALSE,"LT Earn.Dil.";#N/A,#N/A,FALSE,"Dil. AVP"}
Name ________________df2: {#N/A,#N/A,FALSE,"Calc";#N/A,#N/A,FALSE,"Sensitivity";#N/A,#N/A,FALSE,"LT Earn.Dil.";#N/A,#N/A,FALSE,"Dil. AVP"}
Name ________________df2: {#N/A,#N/A,FALSE,"Calc";#N/A,#N/A,FALSE,"Sensitivity";#N/A,#N/A,FALSE,"LT Earn.Dil.";#N/A,#N/A,FALSE,"Dil. AVP"}
Name ________________hd1: {#N/A,#N/A,FALSE,"Calc";#N/A,#N/A,FALSE,"Sensitivity";#N/A,#N/A,FALSE,"LT Earn.Dil.";#N/A,#N/A,FALSE,"Dil. AVP"}
Name ________________hd1: {#N/A,#N/A,FALSE,"Calc";#N/A,#N/A,FALSE,"Sensitivity";#N/A,#N/A,FALSE,"LT Earn.Dil.";#N/A,#N/A,FALSE,"Dil. AVP"}

Sheet Summary
A1: 301 E. ATLANTIC POMPANO BEACH | AP1: FONT KEY
AP2: Blue = Input cell
AP3: Black = Text or formula cell
G4: BUYER'S PREFERRED | S4: PROJECTED STRIKE | AE4: OPTIMISTIC | AP4: Red = Link to Garden input
D5: LAND, UNIT INVENTORY & VALUATION | AP5: Green = Link to Summary input
D6: (Subject to site plan approval)
E7: Land Area | G7: ='Low Budget'!$H$6 -> 2.3362029 | S7: ='Middle Budget'!$H$6 -> 2.3362029 | AE7: ='High Budget'!$H$6 -> 2.3362029
E8: Density | G8: ='Low Budget'!$H$7 -> 149.81575 | S8: ='Middle Budget'!$H$7 -> 149.81575 | AE8: ='High Budget'!$H$7 -> 149.81575
E9: Total Units | G9: ='Low Budget'!$H$11 -> 350 | S9: ='Middle Budget'!$H$11 -> 350 | AE9: ='High Budget'!$H$11 -> 350
E10: Average Unit Size | G10: ='Low NOI'!$H$14 -> 750 | S10: ='Middle NOI'!$H$14 -> 750 | AE10: ='High NOI'!$H$14 -> 750
E11: Net Rentable Area | G11: ='Low NOI'!$I$14 -> 262500 | S11: ='Middle NOI'!$I$14 -> 262500 | AE11: ='High NOI'!$I$14 -> 262500
E12: Total Land Value | G12: =G13*G9 -> 12250000 | S12: =S13*S9 -> 13300000 | AE12: =AE13*AE9 -> 14875000
E13: Land Value Per Unit | G13: 35000 | S13: 38000 | AE13: 42500
E14: Land Value Per Acre | G14: =G12/G7 -> 5243551.3 | S14: =S12/S7 -> 5692998.6 | AE14: =AE12/AE7 -> 6367169.5
E15: Un-Trended ROC (NOI w/ developer RE taxes) | G15: ='Low Budget'!$V$29 -> 0.065602891 | S15: ='Middle Budget'!$V$29 -> 0.064949134 | AE15: ='High Budget'!$V$29 -> 0.06399257
E16: Net Profit as % of Cost (excl. operating cash flow) | G16: ='Low Budget'!$V$30 -> 0.3620037 | S16: ='Middle Budget'!$V$30 -> 0.34843083 | AE16: ='High Budget'!$V$30 -> 0.32857128
E17: IRR on Sale (incl. operating cash flow) | G17: ='Low Budget'!$V$31 -> 0.24813606 | S17: ='Middle Budget'!$V$31 -> 0.24086857 | AE17: ='High Budget'!$V$31 -> 0.23005278
E18: Equity Multiple on Sale (incl. operating cash flow) | G18: ='Low Budget'!$V$32 -> 2.0922063 | S18: ='Middle Budget'!$V$32 -> 2.0519088 | AE18: ='High Budget'!$V$32 -> 1.9929463
E19: Investment Period | G19: ='Low Budget'!$H$27 -> 40 | S19: ='Middle Budget'!$H$27 -> 40 | AE19: ='High Budget'!$H$27 -> 40
D21: RENT & NOI | G21: Studio | I21: 1BR | K21: 2BR | M21: Total | S21: Studio | U21: 1BR | W21: 2BR | Y21: Total | AE21: Studio | AG21: 1BR | AI21: 2BR | AK21: Total
E22: Unit Count | G22: ='Low NOI'!F10 -> 70 | I22: ='Low NOI'!F11 -> 140 | K22: ='Low NOI'!F12 -> 140 | M22: ='Low NOI'!F14 -> 350 | S22: 70 | U22: 140 | W22: 140 | Y22: =S22+U22+W22 -> 350 | AE22: ='High NOI'!F10 -> 70 | AG22: ='High NOI'!F11 -> 140 | AI22: ='High NOI'!F12 -> 140 | AK22: ='Low NOI'!F14 -> 350
E23: % of Total Units | G23: =G22/$M$22 -> 0.2 | I23: =I22/$M$22 -> 0.4 | K23: =K22/$M$22 -> 0.4 | M23: =G23+I23+K23 -> 1 | S23: =S22/$Y$22 -> 0.2 | U23: =U22/$Y$22 -> 0.4 | W23: =W22/$Y$22 -> 0.4 | Y23: =S23+U23+W23 -> 1 | AE23: =AE22/$AK$22 -> 0.2 | AG23: =AG22/$AK$22 -> 0.4 | AI23: =AI22/$AK$22 -> 0.4 | AK23: =AE23+AG23+AI23 -> 1
E24: Average SF Per Unit | G24: ='Low NOI'!$H$10 -> 500 | I24: ='Low NOI'!$H$11 -> 675 | K24: ='Low NOI'!$H$12 -> 950 | M24: ='Low NOI'!$H$14 -> 750 | S24: 500 | U24: 675 | W24: 950 | Y24: ='Middle NOI'!$H$14 -> 750 | AE24: ='High NOI'!$H$10 -> 500 | AG24: ='High NOI'!$H$11 -> 675 | AI24: ='High NOI'!$H$12 -> 950 | AK24: ='High NOI'!$H$14 -> 750
E25: Un-Trended Average Rent Per Unit | G25: =S25 -> 2100 | I25: =U25 -> 2650 | K25: =W25 -> 3150 | M25: ='Low NOI'!K14 -> 2740 | S25: 2100 | U25: 2650 | W25: 3150 | Y25: ='Middle NOI'!K14 -> 2740 | AE25: =S25 -> 2100 | AG25: =U25 -> 2650 | AI25: =W25 -> 3150 | AK25: ='High NOI'!K14 -> 2740
E26: Un-Trended Average Rent Per SF | G26: ='Low NOI'!M10 -> 4.2 | I26: ='Low NOI'!M11 -> 3.9259259 | K26: ='Low NOI'!M12 -> 3.3157895 | M26: ='Low NOI'!M14 -> 3.6533333 | S26: ='Middle NOI'!M10 -> 4.2 | U26: ='Middle NOI'!M11 -> 3.9259259 | W26: ='Middle NOI'!M12 -> 3.3157895 | Y26: ='Middle NOI'!M14 -> 3.6533333 | AE26: ='High NOI'!M10 -> 4.2 | AG26: ='High NOI'!M11 -> 3.9259259 | AI26: ='High NOI'!M12 -> 3.3157895 | AK26: ='High NOI'!M14 -> 3.6533333
E28: Un-Trended NOI (w/ developer RE taxes) | G28: ='Low Budget'!$H$16 -> 7738141.7 | I28: =I105 -> 0.67241412 | S28: ='Middle Budget'!$H$16 -> 7738141.7 | U28: =U105 -> 0.67241412 | AE28: ='High Budget'!$H$16 -> 7738141.7 | AG28: =AG105 -> 0.67241412
D30: LEASE-UP & EXIT VALUE
E31: Lease-Up Velocity | G31: =$S$31 -> 12 | I31: ='Low Budget'!$H$25 -> 25.576923 | S31: 12 | U31: ='Middle Budget'!$H$25 -> 25.576923 | AE31: =$S$31 -> 12 | AG31: ='High Budget'!$H$25 -> 25.576923
E32: Market Cap Rate | G32: =$S$32 -> 0.0475 | S32: 0.0475 | AE32: =$S$32 -> 0.0475
E33: Stabilized Value (trended) | G33: ='Low Budget'!$R$18 -> 1.6268776e+08 | I33: =G33/G9 -> 464822.17 | S33: ='Middle Budget'!$R$18 -> 1.6268776e+08 | U33: =S33/S9 -> 464822.17 | AE33: ='High Budget'!$R$18 -> 1.6268776e+08 | AG33: =AE33/AE9 -> 464822.17
I34: =G33/G11 -> 619.7629 | U34: =S33/S11 -> 619.7629 | AG34: =AE33/AE11 -> 619.7629
D35: DEVELOPMENT COSTS
E36: Hard Costs (excl. impact fees, permits, utility connect) | G36: =$S$36 -> 315 | I36: =G67/G9 -> 248062.5 | K36: ='Low Budget'!$L$76/'Low Budget'!$H$9 -> 165.375 | S36: 315 | U36: =S67/S9 -> 248062.5 | W36: ='Middle Budget'!$L$76/'Middle Budget'!$H$9 -> 165.375 | AE36: =$S$36 -> 315 | AG36: =AE67/AE9 -> 248062.5 | AI36: ='High Budget'!$L$76/'High Budget'!$H$9 -> 165.375
E37: Hard Cost Contingency | G37: =$S$37 -> 0.05 | S37: 0.05 | AE37: =$S$37 -> 0.05
E38: Soft Costs as % of Hard Cost Excluding Financing | G38: ='Low Budget'!$L$88/'Low Budget'!$L$76 -> 0.14093274 | S38: ='Middle Budget'!$L$88/'Middle Budget'!$L$76 -> 0.1413273 | AE38: ='High Budget'!$L$88/'High Budget'!$L$76 -> 0.14191912
E39: Soft Costs as % of Hard Cost Including Financing | G39: =('Low Budget'!$L$88+'Low Budget'!$L$98+'Low Budget'!$L$102+'Low Budget'!$L$108)/'Low Budget'!$L$76 -> 0.21748441 | S39: =('Middle Budget'!$L$88+'Middle Budget'!$L$98+'Middle Budget'!$L$102+'Middle Budget'!$L$108)/'Middle Budget'!$L$76 -> 0.21906569 | AE39: =('High Budget'!$L$88+'High Budget'!$L$98+'High Budget'!$L$102+'High Budget'!$L$108)/'High Budget'!$L$76 -> 0.2214376
E40: Developer Fee as % of Cost Excl. Land & Financing | G40: =$S$40 -> 0.03 | I40: ='Low Budget'!$L$87 -> 2885182.1 | S40: 0.03 | U40: ='Middle Budget'!$L$87 -> 2886179.9 | AE40: =$S$40 -> 0.03 | AG40: ='High Budget'!$L$87 -> 2887676.5
E41: Developer Fee as % of Total Cost | G41: ='Low Budget'!$R$87 -> 0.024460174 | S41: ='Middle Budget'!R87 -> 0.024224793 | AE41: ='High Budget'!R87 -> 0.02388039
E42: Construction Period | G42: =$S$42 -> 24 | S42: 24 | AE42: =$S$42 -> 24
E43: Total Development Cost (including land) | G43: ='Low Budget'!$L$110 -> 1.1795428e+08 | I43: =G43/G9 -> 337012.23 | S43: ='Middle Budget'!$L$110 -> 1.1914157e+08 | U43: =S43/S9 -> 340404.48 | AE43: ='High Budget'!$L$110 -> 1.209225e+08 | AG43: =AE43/AE9 -> 345492.86
...

Sheet BOV TABLES
A1: =Summary!A1 -> 301 E. ATLANTIC POMPANO BEACH
G4: BUYER'S PREFERRED | O4: PROJECTED STRIKE | W4: OPTIMISTIC
D5: VALUATION
D6: (Subject to site plan approval)
E7: Total Land Value | G7: =Summary!G12 -> 12250000 | O7: =Summary!S12 -> 13300000 | W7: =Summary!AE12 -> 14875000
E8: Land Value Per Unit | G8: =Summary!G13 -> 35000 | O8: =Summary!S13 -> 38000 | W8: =Summary!AE13 -> 42500
E9: Land Value Per Acre | G9: =Summary!G14 -> 5243551.3 | O9: =Summary!S14 -> 5692998.6 | W9: =Summary!AE14 -> 6367169.5
D11: RETURNS - MERCHANT BUILD
E12: Un-Trended ROC (NOI w/ developer RE taxes) | G12: =Summary!G15 -> 0.065602891 | O12: =Summary!S15 -> 0.064949134 | W12: =Summary!AE15 -> 0.06399257
E13: Net Profit as % of Cost (excl. net op. CF) | G13: =Summary!G16 -> 0.3620037 | O13: =Summary!S16 -> 0.34843083 | W13: =Summary!AE16 -> 0.32857128
E14: IRR on Sale (incl. net op. CF) | G14: =Summary!G17 -> 0.24813606 | O14: =Summary!S17 -> 0.24086857 | W14: =Summary!AE17 -> 0.23005278
E15: Equity Multiple on Sale (incl. net op. CF) | G15: =Summary!G18 -> 2.0922063 | O15: =Summary!S18 -> 2.0519088 | W15: =Summary!AE18 -> 1.9929463
E16: Investment Period | G16: =Summary!G19 -> 40 | O16: =Summary!S19 -> 40 | W16: =Summary!AE19 -> 40
D18: LAND AREA & UNIT INVENTORY
E19: Land Area | G19: =Summary!G7 -> 2.3362029 | O19: =Summary!S7 -> 2.3362029 | W19: =Summary!AE7 -> 2.3362029
E20: Density | G20: ='Low Budget'!$H$7 -> 149.81575 | O20: ='Middle Budget'!$H$7 -> 149.81575 | W20: ='High Budget'!$H$7 -> 149.81575
E21: Height | G21: ='Low Budget'!$H$8 -> 8 | O21: ='Middle Budget'!$H$8 -> 8 | W21: ='Low Budget'!$H$8 -> 8
E22: Gross Building Area | G22: ='Low Budget'!$H$9 -> 525000 | O22: ='Middle Budget'!$H$9 -> 525000 | W22: ='Low Budget'!$H$9 -> 525000
E23: Building Efficiency | G23: ='Low Budget'!$H$10 -> 0.5 | O23: ='Middle Budget'!$H$10 -> 0.5 | W23: ='Low Budget'!$H$10 -> 0.5
E24: Unit Count | G24: =Summary!G9 -> 350 | O24: =Summary!S9 -> 350 | W24: =Summary!AE9 -> 350
E25: Average Unit Size | G25: =Summary!G10 -> 750 | O25: =Summary!S10 -> 750 | W25: =Summary!AE10 -> 750
E26: Net Rentable Area | G26: =Summary!G11 -> 262500 | O26: =Summary!S11 -> 262500 | W26: =Summary!AE11 -> 262500
D28: RENT & NOI
E29: Un-Trended Average Rent Per Unit | G29: =Summary!M25 -> 2740 | O29: =Summary!Y25 -> 2740 | W29: =Summary!AK25 -> 2740
E30: Un-Trended Average Rent Per SF | G30: =Summary!M26 -> 3.6533333 | O30: =Summary!Y26 -> 3.6533333 | W30: =Summary!AK26 -> 3.6533333
E31: Un-Trended NOI (w/ developer RE taxes) | G31: =Summary!G28 -> 7738141.7 | I31: =Summary!I28 -> 0.67241412 | O31: =Summary!S28 -> 7738141.7 | Q31: =Summary!U28 -> 0.67241412 | W31: =Summary!AE28 -> 7738141.7 | Y31: =Summary!AG28 -> 0.67241412
D33: LEASE-UP & STABILIZED VALUE
E34: Lease-Up Velocity | G34: =Summary!G31 -> 12 | I34: =Summary!I31 -> 25.576923 | O34: =Summary!S31 -> 12 | Q34: =Summary!U31 -> 25.576923 | W34: =Summary!AE31 -> 12 | Y34: =Summary!AG31 -> 25.576923
E35: Market Cap Rate | G35: =Summary!G32 -> 0.0475 | O35: =Summary!S32 -> 0.0475 | W35: =Summary!AE32 -> 0.0475
E36: Stabilized Value (trended) | G36: =Summary!G33 -> 1.6268776e+08 | I36: =Summary!I33 -> 464822.17 | O36: =Summary!S33 -> 1.6268776e+08 | Q36: =Summary!U33 -> 464822.17 | W36: =Summary!AE33 -> 1.6268776e+08 | Y36: =Summary!AG33 -> 464822.17
I37: =Summary!I34 -> 619.7629 | Q37: =Summary!U34 -> 619.7629 | Y37: =Summary!AG34 -> 619.7629
D38: DEVELOPMENT COST ASSUMPTIONS
E39: Hard Costs (excl. impact fees, permits, utility connect) | G39: =Summary!G36 -> 315 | I39: =Summary!I36 -> 248062.5 | K39: ='Low Budget'!$L$76/'Low Budget'!$H$9 -> 165.375 | O39: =Summary!S36 -> 315 | Q39: =Summary!U36 -> 248062.5 | S39: ='Middle Budget'!$L$76/'Middle Budget'!$H$9 -> 165.375 | W39: =Summary!AE36 -> 315 | Y39: =Summary!AG36 -> 248062.5 | AA39: ='High Budget'!$L$76/'High Budget'!$H$9 -> 165.375
E40: Hard Cost Contingency | G40: =Summary!G37 -> 0.05 | O40: =Summary!S37 -> 0.05 | W40: =Summary!AE37 -> 0.05
E41: Developer Fee as % of Cost Excl. Land & Financing | G41: =Summary!G40 -> 0.03 | I41: =Summary!I40 -> 2885182.1 | O41: =Summary!S40 -> 0.03 | Q41: =Summary!U40 -> 2886179.9 | W41: =Summary!AE40 -> 0.03 | Y41: =Summary!AG40 -> 2887676.5
E42: Construction Period | G42: =Summary!G42 -> 24 | O42: =Summary!S42 -> 24 | W42: =Summary!AE42 -> 24
E43: Total Development Cost (land, hard and soft) | G43: =Summary!G43 -> 1.1795428e+08 | I43: =Summary!I43 -> 337012.23 | O43: =Summary!S43 -> 1.1914157e+08 | Q43: =Summary!U43 -> 340404.48 | W43: =Summary!AE43 -> 1.209225e+08 | Y43: =Summary!AG43 -> 345492.86
I44: =Summary!I44 -> 449.34963 | Q44: =Summary!U44 -> 453.87264 | Y44: =Summary!AG44 -> 460.65715
G48: =$G$4 -> BUYER'S PREFERRED | O48: =$O$4 -> PROJECTED STRIKE | W48: =$W$4 -> OPTIMISTIC
D50: DEVELOPMENT CAPITALIZATION | G50: Total | I50: % Cost | O50: Total | Q50: % Cost | W50: Total | Y50: % Cost
...

Sheet Middle Budget
A1: =Summary!$A$1&" - "&Summary!$S$4 -> 301 E. ATLANTIC POMPANO BEACH - PROJECTED STRIKE | Z1: FONT KEY
Z2: Blue = Input cell
Z3: Red = Link to Summary
C4: UNIT SUMMARY | L4: PROJECTED PROFIT ON SALE AT STABILIZATION | Z4: Black = Text or formula cell
E6: Development Land Area | H6: =(54965+46800)/43560 -> 2.3362029
E7: Density | H7: =H11/H6 -> 149.81575 | L7: Stabilized Value | T7: Sale / Refi | V7: Stabilization
E8: Height | H8: 8 | T8: =H27 -> 40 | V8: =H26 -> 37
E9: Gross Building Area | H9: =H12/H10 -> 525000 | L9: NOI with Developer Property Taxes | R9: RE Tax | T9: =LOOKUP(H27,'Middle ICF'!K3:EX3,'Middle ICF'!K61:EX61)*12 -> 8480558.3 | V9: =LOOKUP(H26,'Middle ICF'!K3:EX3,'Middle ICF'!K61:EX61)*12 -> 8413315.5
E10: Building Efficiency | H10: 0.5 | L10: Add Back: Developer Property Taxes | R10: Reassessment | T10: =LOOKUP(H27,'Middle ICF'!K3:EX3,'Middle ICF'!K57:EX57)*12 -> 1648510.6 | V10: =LOOKUP(H26,'Middle ICF'!K3:EX3,'Middle ICF'!K57:EX57)*12 -> 1638365.4
E11: Unit Count - Total | H11: ='Middle NOI'!F14 -> 350 | L11: Less: Taxes with Market Value Reassessment | R11: 0.75 | T11: =-T14*$R$11*$R$12*(1-R13) -> -2401400.2 | V11: =-V14*R11*R12*(1-R13) -> -2383053.1
E12: Net Rentable Area | H12: ='Middle NOI'!I14 -> 262500 | L12: NOI After Market Value Tax Reassessment | R12: 0.0205011 | T12: =SUM(T9:T11) -> 7727668.7 | V12: =SUM(V9:V11) -> 7668627.8
E13: Average Unit Size | H13: =H12/H11 -> 750 | L13: Market Cap Rate | R13: 0.04 | T13: =Summary!S32 -> 0.0475 | V13: =Summary!S32 -> 0.0475
E14: Un-Trended Average Rent Per Unit | H14: ='Middle NOI'!K14 -> 2740 | L14: Estimated Market Value | T14: =IF(ABS(T13)>0,T12/T13,0) -> 1.6268776e+08 | V14: =IF(ABS(V13)>0,V12/V13,0) -> 1.614448e+08
E15: Un-Trended Average Rent Per SF | H15: ='Middle NOI'!M14 -> 3.6533333
E16: Un-Trended NOI (developer property taxes) | H16: ='Middle NOI'!K62 -> 7738141.7 | L16: Net Profit on Sale at Stabilization
R17: Total | T17: Per Unit | V17: Per SF
C18: PROJECTED TIMING | L18: Value at Sale Date | R18: =T14 -> 1.6268776e+08 | T18: =R18/$H$11 -> 464822.17 | V18: =R18/$H$12 -> 619.7629
L19: 0.0125 | R19: =R18*-L19 -> -2033597 | T19: =R19/$H$11 -> -5810.2772 | V19: =R19/$H$12 -> -7.7470362
E20: Hard Cost Draws Start | H20: 1 | L20: Net Sale Proceeds | R20: =SUM(R18:R19) -> 1.6065416e+08 | T20: =R20/$H$11 -> 459011.9 | V20: =R20/$H$12 -> 612.01586
E21: Hard Cost Draws End | H21: =Summary!S42 -> 24 | L21: Less: Total Land & Development Cost | R21: =-L110 -> -1.1914157e+08 | T21: =R21/$H$11 -> -340404.48 | V21: =R21/$H$12 -> -453.87264
E22: Soft Cost Draws Start Excl. Op. Deficit | H22: 1 | L22: Net Profit on Sale | R22: =SUM(R20:R21) -> 41512595 | T22: =R22/$H$11 -> 118607.42 | V22: =R22/$H$12 -> 158.14322
E23: 2 | H23: =H21+E23 -> 26 | L23: Add: Operating Cash Flow After Debt Service | R23: ='Middle ICF'!I104-'Middle ICF'!I115 -> 2209429 | T23: =R23/$H$11 -> 6312.6542 | V23: =R23/$H$12 -> 8.4168723
E24: 1 | H24: =H21+E24 -> 25 | L24: Total Net Profit | R24: =SUM(R22:R23) -> 43722024 | T24: =R24/$H$11 -> 124920.07 | V24: =R24/$H$12 -> 166.56009
E25: Average Monthly Move-Ins | H25: =(H11*(1-'Middle NOI'!$Y$9))/(H26-H24+1) -> 25.576923
E26: =Summary!S31 -> 12 | H26: =H24+E26 -> 37 | L26: RETURN METRICS
E27: 3 | H27: =H26+E27 -> 40
L28: Merchant Build
C29: CONSTRUCTION FINANCING ASSUMPTIONS | L29: Untrended Return on Cost (NOI with developer property taxes) | V29: =H16/L110 -> 0.064949134
L30: Net Profit as % of Cost (excl. net op. CF) | V30: =IF(ABS(R21)>0,-R22/R21,0) -> 0.34843083
E31: Maximum Loan to Cost | H31: 0.65 | L31: IRR on Sale at Stabilization (incl. net op. CF) | V31: ='Middle ICF'!F110 -> 0.24086857
E32: Maximum % of Stabilized Value | H32: 0.55 | L32: Equity Multiple on Sale at Stabilization (incl. net op. CF) | V32: =(R24+L49)/L49 -> 2.0519088
E33: Minimum Un-Trended Debt Yield (NOI with developer property taxes) | H33: 0.085
E34: Interest Rate - Projected Average Index | H34: 0.035 | L34: Permanent Refinancing
E35: Interest Rate - Spread | H35: 0.025 | L35: Post-Permanent Refinancing Cash-on-Cash Return - Interest Only | V35: =L155 -> 0.13289198
E36: Interest Rate - Total | H36: =H34+H35 -> 0.06 | L36: Post-Permanent Refinancing Cash-on-Cash Return - Amortizing | V36: =H155 -> 0.077459385
E37: Minimum Interest - Months | H37: 12
E38: Minimum Interest - Amount | H38: =L48*H36/12*H37 -> 4631468.9
E39: Origination Fee | H39: 0.01
E40: Exit Fee | H40: 0.005
B44: SOURCES & USES | T44: Untrended | V44: % Stabilized
...

Sheet Middle NOI
A1: ='Middle Budget'!A1 -> 301 E. ATLANTIC POMPANO BEACH - PROJECTED STRIKE
B5: UNIT MIX & MARKET RENT | R5: OPERATING ASSUMPTIONS
K6: Untrended Rent
S7: Annual Rent & Other Income Growth | Y7: 0.03
F8: Units | G8: % Units | H8: Avg. SF | I8: Total SF | K8: Per Unit | M8: Per SF | O8: Total $ | S8: Loss-to-Lease (% of market rent) | Y8: 0.01
S9: Stabilized Vacancy (% of market rent) | Y9: 0.05
E10: Studio | F10: =Summary!S22 -> 70 | G10: =F10/$F$14 -> 0.2 | H10: =Summary!S24 -> 500 | I10: =F10*H10 -> 35000 | K10: =Summary!S25 -> 2100 | M10: =O10/I10 -> 4.2 | O10: =F10*K10 -> 147000 | S10: Collection Loss (% of GPR) | Y10: 0.0025
E11: One Bedroom | F11: =Summary!U22 -> 140 | G11: =F11/$F$14 -> 0.4 | H11: =Summary!U24 -> 675 | I11: =F11*H11 -> 94500 | K11: =Summary!U25 -> 2650 | M11: =O11/I11 -> 3.9259259 | O11: =F11*K11 -> 371000 | S11: Annual Operating Expense Growth | Y11: 0.025
E12: Two Bedroom | F12: =Summary!W22 -> 140 | G12: =F12/$F$14 -> 0.4 | H12: =Summary!W24 -> 950 | I12: =F12*H12 -> 133000 | K12: =Summary!W25 -> 3150 | M12: =O12/I12 -> 3.3157895 | O12: =F12*K12 -> 441000 | S12: 0.75 | Y12: 0.25
S13: Management Fee (% of total revenue) | Y13: 0.02
F14: =SUM(F10:F13) -> 350 | G14: =SUM(G10:G13) -> 1 | H14: =I14/F14 -> 750 | I14: =SUM(I10:I13) -> 262500 | K14: =O14/F14 -> 2740 | M14: =O14/I14 -> 3.6533333 | O14: =SUM(O10:O13) -> 959000 | S14: Management Fee Monthly Minimum Until Stabilization | Y14: 5000
S15: Replacement Reserve Per Unit Annually | Y15: 200
S19: Year of Operations
B20: PROJECTED OPERATING RESULTS | S20: 1 | U20: 2 | W20: 3 | Y20: 4 | AA20: 5
S21: =LOOKUP('Middle ICF'!$C$14,'Middle ICF'!$K$3:$EX$3,'Middle ICF'!$K$6:$EX$6) -> Lease-Up | U21: =LOOKUP('Middle ICF'!$C$14+12,'Middle ICF'!$K$3:$EX$3,'Middle ICF'!$K$6:$EX$6) -> Stabilized | W21: =LOOKUP('Middle ICF'!$C$14+24,'Middle ICF'!$K$3:$EX$3,'Middle ICF'!$K$6:$EX$6) -> Stabilized | Y21: =LOOKUP('Middle ICF'!$C$14+36,'Middle ICF'!$K$3:$EX$3,'Middle ICF'!$K$6:$EX$6) -> Stabilized | AA21: =LOOKUP('Middle ICF'!$C$14+48,'Middle ICF'!$K$3:$EX$3,'Middle ICF'!$K$6:$EX$6) -> Stabilized
R23: Beginning Avg. Monthly Rent: | S23: =LOOKUP('Middle ICF'!$C$14+1,'Middle ICF'!$K$3:$EX$3,'Middle ICF'!$K$28:$EX$28) -> 2921.2219 | U23: =LOOKUP('Middle ICF'!$C$14+1+12,'Middle ICF'!$K$3:$EX$3,'Middle ICF'!$K$28:$EX$28) -> 3008.8586 | W23: =LOOKUP('Middle ICF'!$C$14+1+24,'Middle ICF'!$K$3:$EX$3,'Middle ICF'!$K$28:$EX$28) -> 3099.1243 | Y23: =LOOKUP('Middle ICF'!$C$14+1+36,'Middle ICF'!$K$3:$EX$3,'Middle ICF'!$K$28:$EX$28) -> 3192.0981 | AA23: =LOOKUP('Middle ICF'!$C$14+1+48,'Middle ICF'!$K$3:$EX$3,'Middle ICF'!$K$28:$EX$28) -> 3287.861
R24: Ending Avg. Monthly Rent: | S24: =LOOKUP('Middle ICF'!$C$14+12,'Middle ICF'!$K$3:$EX$3,'Middle ICF'!$K$28:$EX$28) -> 3001.4562 | U24: =LOOKUP('Middle ICF'!$C$14+12+12,'Middle ICF'!$K$3:$EX$3,'Middle ICF'!$K$28:$EX$28) -> 3091.4999 | W24: =LOOKUP('Middle ICF'!$C$14+12+24,'Middle ICF'!$K$3:$EX$3,'Middle ICF'!$K$28:$EX$28) -> 3184.2448 | Y24: =LOOKUP('Middle ICF'!$C$14+12+36,'Middle ICF'!$K$3:$EX$3,'Middle ICF'!$K$28:$EX$28) -> 3279.7722 | AA24: =LOOKUP('Middle ICF'!$C$14+12+48,'Middle ICF'!$K$3:$EX$3,'Middle ICF'!$K$28:$EX$28) -> 3378.1654
R25: Rent Growth % (begin to begin): | S25: 0 | U25: =(U23-S23)/S23 -> 0.03 | W25: =(W23-U23)/U23 -> 0.03 | Y25: =(Y23-W23)/W23 -> 0.03 | AA25: =(AA23-Y23)/Y23 -> 0.03
R26: Average Vacancy: | S26: =-S37/S33 -> 0.44977804 | U26: =-U37/U33 -> 0.05 | W26: =-W37/W33 -> 0.05 | Y26: =-Y37/Y33 -> 0.05 | AA26: =-AA37/AA33 -> 0.05
R27: NOI as % of Market Rent: | S27: =S62/S33 -> 0.3437779 | U27: =U62/U33 -> 0.64432249 | W27: =W62/W33 -> 0.64595275 | Y27: =Y62/Y33 -> 0.64757123 | AA27: =AA62/AA33 -> 0.6491781
R28: NOI Growth: | S28: 0 | U28: =(U62-S62)/S62 -> 0.93046781 | W28: =(W62-U62)/U62 -> 0.032606093 | Y28: =(Y62-W62)/W62 -> 0.032580737 | AA28: =(AA62-Y62)/Y62 -> 0.032555825
K30: Untrended
C31: Income | K31: Total | M31: Per Unit | O31: % Mkt
E33: Market Rent | K33: =F14*K14*12 -> 11508000 | M33: =K33/$F$14 -> 32880 | O33: =K33/K$33 -> 1 | S33: =SUMIF('Middle ICF'!$K$5:$EX$5,S$20,'Middle ICF'!$K35:$EX35) -> 12436932 | U33: =SUMIF('Middle ICF'!$K$5:$EX$5,U$20,'Middle ICF'!$K35:$EX35) -> 12810040 | W33: =SUMIF('Middle ICF'!$K$5:$EX$5,W$20,'Middle ICF'!$K35:$EX35) -> 13194341 | Y33: =SUMIF('Middle ICF'!$K$5:$EX$5,Y$20,'Middle ICF'!$K35:$EX35) -> 13590172 | AA33: =SUMIF('Middle ICF'!$K$5:$EX$5,AA$20,'Middle ICF'!$K35:$EX35) -> 13997877
D34: (a) | E34: Loss-to-Lease | K34: 0 | M34: =K34/$F$14 -> 0 | O34: =K34/K$33 -> 0 | S34: =SUMIF('Middle ICF'!$K$5:$EX$5,S$20,'Middle ICF'!$K36:$EX36) -> -10505.097 | U34: =SUMIF('Middle ICF'!$K$5:$EX$5,U$20,'Middle ICF'!$K36:$EX36) -> -128100.4 | W34: =SUMIF('Middle ICF'!$K$5:$EX$5,W$20,'Middle ICF'!$K36:$EX36) -> -131943.41 | Y34: =SUMIF('Middle ICF'!$K$5:$EX$5,Y$20,'Middle ICF'!$K36:$EX36) -> -135901.72 | AA34: =SUMIF('Middle ICF'!$K$5:$EX$5,AA$20,'Middle ICF'!$K36:$EX36) -> -139978.77
E35: Gross Potential Rent | K35: =SUM(K33:K34) -> 11508000 | M35: =K35/$F$14 -> 32880 | O35: =K35/K$33 -> 1 | S35: =SUM(S33:S34) -> 12426427 | U35: =SUM(U33:U34) -> 12681940 | W35: =SUM(W33:W34) -> 13062398 | Y35: =SUM(Y33:Y34) -> 13454270 | AA35: =SUM(AA33:AA34) -> 13857898
E37: Vacancy | K37: =-K33*$Y9 -> -575400 | M37: =K37/$F$14 -> -1644 | O37: =K37/K$33 -> -0.05 | S37: =SUMIF('Middle ICF'!$K$5:$EX$5,S$20,'Middle ICF'!$K39:$EX39) -> -5593859 | U37: =SUMIF('Middle ICF'!$K$5:$EX$5,U$20,'Middle ICF'!$K39:$EX39) -> -640502.01 | W37: =SUMIF('Middle ICF'!$K$5:$EX$5,W$20,'Middle ICF'!$K39:$EX39) -> -659717.07 | Y37: =SUMIF('Middle ICF'!$K$5:$EX$5,Y$20,'Middle ICF'!$K39:$EX39) -> -679508.58 | AA37: =SUMIF('Middle ICF'!$K$5:$EX$5,AA$20,'Middle ICF'!$K39:$EX39) -> -699893.84
E38: Collection Loss | K38: =-K35*$Y10 -> -28770 | M38: =K38/$F$14 -> -82.2 | O38: =K38/K$33 -> -0.0025 | S38: =SUMIF('Middle ICF'!$K$5:$EX$5,S$20,'Middle ICF'!$K40:$EX40) -> -31066.068 | U38: =SUMIF('Middle ICF'!$K$5:$EX$5,U$20,'Middle ICF'!$K40:$EX40) -> -31704.85 | W38: =SUMIF('Middle ICF'!$K$5:$EX$5,W$20,'Middle ICF'!$K40:$EX40) -> -32655.995 | Y38: =SUMIF('Middle ICF'!$K$5:$EX$5,Y$20,'Middle ICF'!$K40:$EX40) -> -33635.675 | AA38: =SUMIF('Middle ICF'!$K$5:$EX$5,AA$20,'Middle ICF'!$K40:$EX40) -> -34644.745
E39: Net Rental Income | K39: =SUM(K35:K38) -> 10903830 | M39: =K39/$F$14 -> 31153.8 | O39: =K39/K$33 -> 0.9475 | S39: =SUM(S35:S38) -> 6801502 | U39: =SUM(U35:U38) -> 12009733 | W39: =SUM(W35:W38) -> 12370025 | Y39: =SUM(Y35:Y38) -> 12741126 | AA39: =SUM(AA35:AA38) -> 13123359
E40: 0.8 | K40: =E40*K51 -> 280000 | M40: =K40/$F$14 -> 800 | O40: =K40/K$33 -> 0.0243309 | S40: =SUMIF('Middle ICF'!$K$5:$EX$5,S$20,'Middle ICF'!$K42:$EX42) -> 298757.72 | U40: =SUMIF('Middle ICF'!$K$5:$EX$5,U$20,'Middle ICF'!$K42:$EX42) -> 306226.66 | W40: =SUMIF('Middle ICF'!$K$5:$EX$5,W$20,'Middle ICF'!$K42:$EX42) -> 313882.33 | Y40: =SUMIF('Middle ICF'!$K$5:$EX$5,Y$20,'Middle ICF'!$K42:$EX42) -> 321729.39 | AA40: =SUMIF('Middle ICF'!$K$5:$EX$5,AA$20,'Middle ICF'!$K42:$EX42) -> 329772.62
E41: Parking & Other Income | K41: ='Middle OtherInc'!M21 -> 399945 | M41: =K41/$F$14 -> 1142.7 | O41: =K41/K$33 -> 0.03475365 | S41: =SUMIF('Middle ICF'!$K$5:$EX$5,S$20,'Middle ICF'!$K43:$EX43) -> 239647.22 | U41: =SUMIF('Middle ICF'!$K$5:$EX$5,U$20,'Middle ICF'!$K43:$EX43) -> 445195.65 | W41: =SUMIF('Middle ICF'!$K$5:$EX$5,W$20,'Middle ICF'!$K43:$EX43) -> 458551.52 | Y41: =SUMIF('Middle ICF'!$K$5:$EX$5,Y$20,'Middle ICF'!$K43:$EX43) -> 472308.06 | AA41: =SUMIF('Middle ICF'!$K$5:$EX$5,AA$20,'Middle ICF'!$K43:$EX43) -> 486477.31
D42: Total Revenue | K42: =SUM(K39:K41) -> 11583775 | M42: =K42/$F$14 -> 33096.5 | O42: =K42/K$33 -> 1.0065845 | S42: =S39+S41 -> 7041149.3 | U42: =U39+U41 -> 12454929 | W42: =W39+W41 -> 12828576 | Y42: =Y39+Y41 -> 13213434 | AA42: =AA39+AA41 -> 13609837
C44: Operating Expenses
E46: Payroll | K46: ='Middle Payroll'!R11 -> 538200 | M46: =K46/$F$14 -> 1537.7143 | O46: =K46/K$33 -> 0.046767466 | S46: =SUMIF('Middle ICF'!$K$5:$EX$5,S$20,'Middle ICF'!$K48:$EX48) -> 574255.02 | U46: =SUMIF('Middle ICF'!$K$5:$EX$5,U$20,'Middle ICF'!$K48:$EX48) -> 588611.39 | W46: =SUMIF('Middle ICF'!$K$5:$EX$5,W$20,'Middle ICF'!$K48:$EX48) -> 603326.68 | Y46: =SUMIF('Middle ICF'!$K$5:$EX$5,Y$20,'Middle ICF'!$K48:$EX48) -> 618409.84 | AA46: =SUMIF('Middle ICF'!$K$5:$EX$5,AA$20,'Middle ICF'!$K48:$EX48) -> 633870.09 | AC46: =SUMIF('Middle ICF'!$K$5:$EX$5,AC$20,'Middle ICF'!$K48:$EX48) -> 0
E47: General & Administrative | K47: =$F$14*M47 -> 87500 | M47: 250 | O47: =K47/K$33 -> 0.0076034063 | S47: =SUMIF('Middle ICF'!$K$5:$EX$5,S$20,'Middle ICF'!$K49:$EX49) -> 93361.787 | U47: =SUMIF('Middle ICF'!$K$5:$EX$5,U$20,'Middle ICF'!$K49:$EX49) -> 95695.832 | W47: =SUMIF('Middle ICF'!$K$5:$EX$5,W$20,'Middle ICF'!$K49:$EX49) -> 98088.228 | Y47: =SUMIF('Middle ICF'!$K$5:$EX$5,Y$20,'Middle ICF'!$K49:$EX49) -> 100540.43 | AA47: =SUMIF('Middle ICF'!$K$5:$EX$5,AA$20,'Middle ICF'!$K49:$EX49) -> 103053.94 | AC47: =SUMIF('Middle ICF'!$K$5:$EX$5,AC$20,'Middle ICF'!$K49:$EX49) -> 0
E48: Repairs & Maintenance | K48: =$F$14*M48 -> 87500 | M48: 250 | O48: =K48/K$33 -> 0.0076034063 | S48: =SUMIF('Middle ICF'!$K$5:$EX$5,S$20,'Middle ICF'!$K50:$EX50) -> 7868.502 | U48: =SUMIF('Middle ICF'!$K$5:$EX$5,U$20,'Middle ICF'!$K50:$EX50) -> 95695.832 | W48: =SUMIF('Middle ICF'!$K$5:$EX$5,W$20,'Middle ICF'!$K50:$EX50) -> 98088.228 | Y48: =SUMIF('Middle ICF'!$K$5:$EX$5,Y$20,'Middle ICF'!$K50:$EX50) -> 100540.43 | AA48: =SUMIF('Middle ICF'!$K$5:$EX$5,AA$20,'Middle ICF'!$K50:$EX50) -> 103053.94 | AC48: =SUMIF('Middle ICF'!$K$5:$EX$5,AC$20,'Middle ICF'!$K50:$EX50) -> 0
E49: Contract Services | K49: =$F$14*M49 -> 175000 | M49: 500 | O49: =K49/K$33 -> 0.015206813 | S49: =SUMIF('Middle ICF'!$K$5:$EX$5,S$20,'Middle ICF'!$K51:$EX51) -> 186723.57 | U49: =SUMIF('Middle ICF'!$K$5:$EX$5,U$20,'Middle ICF'!$K51:$EX51) -> 191391.66 | W49: =SUMIF('Middle ICF'!$K$5:$EX$5,W$20,'Middle ICF'!$K51:$EX51) -> 196176.46 | Y49: =SUMIF('Middle ICF'!$K$5:$EX$5,Y$20,'Middle ICF'!$K51:$EX51) -> 201080.87 | AA49: =SUMIF('Middle ICF'!$K$5:$EX$5,AA$20,'Middle ICF'!$K51:$EX51) -> 206107.89 | AC49: =SUMIF('Middle ICF'!$K$5:$EX$5,AC$20,'Middle ICF'!$K51:$EX51) -> 0
E50: Turnover | K50: =$F$14*M50 -> 87500 | M50: 250 | O50: =K50/K$33 -> 0.0076034063 | S50: =SUMIF('Middle ICF'!$K$5:$EX$5,S$20,'Middle ICF'!$K52:$EX52) -> 7868.502 | U50: =SUMIF('Middle ICF'!$K$5:$EX$5,U$20,'Middle ICF'!$K52:$EX52) -> 95695.832 | W50: =SUMIF('Middle ICF'!$K$5:$EX$5,W$20,'Middle ICF'!$K52:$EX52) -> 98088.228 | Y50: =SUMIF('Middle ICF'!$K$5:$EX$5,Y$20,'Middle ICF'!$K52:$EX52) -> 100540.43 | AA50: =SUMIF('Middle ICF'!$K$5:$EX$5,AA$20,'Middle ICF'!$K52:$EX52) -> 103053.94
E51: Utilities | K51: =$F$14*M51 -> 350000 | M51: 1000 | O51: =K51/K$33 -> 0.030413625 | S51: =SUMIF('Middle ICF'!$K$5:$EX$5,S$20,'Middle ICF'!$K53:$EX53) -> 373447.15 | U51: =SUMIF('Middle ICF'!$K$5:$EX$5,U$20,'Middle ICF'!$K53:$EX53) -> 382783.33 | W51: =SUMIF('Middle ICF'!$K$5:$EX$5,W$20,'Middle ICF'!$K53:$EX53) -> 392352.91 | Y51: =SUMIF('Middle ICF'!$K$5:$EX$5,Y$20,'Middle ICF'!$K53:$EX53) -> 402161.73 | AA51: =SUMIF('Middle ICF'!$K$5:$EX$5,AA$20,'Middle ICF'!$K53:$EX53) -> 412215.78
E52: Leasing & Marketing | K52: =$F$14*M52 -> 87500 | M52: 250 | O52: =K52/K$33 -> 0.0076034063 | S52: =SUMIF('Middle ICF'!$K$5:$EX$5,S$20,'Middle ICF'!$K54:$EX54) -> 93361.787 | U52: =SUMIF('Middle ICF'!$K$5:$EX$5,U$20,'Middle ICF'!$K54:$EX54) -> 95695.832 | W52: =SUMIF('Middle ICF'!$K$5:$EX$5,W$20,'Middle ICF'!$K54:$EX54) -> 98088.228 | Y52: =SUMIF('Middle ICF'!$K$5:$EX$5,Y$20,'Middle ICF'!$K54:$EX54) -> 100540.43 | AA52: =SUMIF('Middle ICF'!$K$5:$EX$5,AA$20,'Middle ICF'!$K54:$EX54) -> 103053.94 | AC52: =SUMIF('Middle ICF'!$K$5:$EX$5,AC$20,'Middle ICF'!$K54:$EX54) -> 0
...

Sheet Middle OtherInc
A1: ='Middle Budget'!A1 -> 301 E. ATLANTIC POMPANO BEACH - PROJECTED STRIKE
B4: PARKING & OTHER INCOME
F5: Assumptions | M5: Annual Total
F6: ='Middle Budget'!H11 -> 350
D8: Reserved Parking | F8: 95 | H8: 0.25 | J8: - | M8: =F8*$F$6*H8*12 -> 99750
D9: Vehicle Registration Fee | F9: 30 | H9: =$H$10 -> 0.45 | J9: 1.5 | M9: =F9*J9*$F$6*H9 -> 7087.5
D10: Application Fees | F10: 150 | H10: 0.45 | J10: - | M10: =F10*$F$6*H10 -> 23625
D11: Pet Fees | F11: 300 | H11: =$H$10 -> 0.45 | J11: 0.25 | M11: =F11*$F$6*H11*J11 -> 11812.5
D12: Pet Rent | F12: 25 | H12: 0.25 | J12: - | M12: =F12*$F$6*H12*12 -> 26250
D13: Trash Collection | F13: 20 | H13: 1 | J13: =1-'Middle NOI'!$Y$9 -> 0.95 | M13: =F13*$F$6*H13*J13*12 -> 79800
D14: Pest Control | F14: 5 | H14: 1 | J14: =1-'Middle NOI'!$Y$9 -> 0.95 | M14: =F14*$F$6*H14*J14*12 -> 19950
D15: Late Fees & NSF Fees | F15: 125 | H15: 5 | J15: - | M15: =F15*H15*12 -> 7500
D16: Lease Termination Fees | F16: ='Middle NOI'!K14 -> 2740 | H16: 3 | J16: - | M16: =F16*H16 -> 8220
D17: Cleaning & Damage Charges | F17: 500 | H17: 2 | J17: - | M17: =F17*H17*12 -> 12000
D18: Cable Revenue Share | F18: 25 | H18: 1 | J18: =1-'Middle NOI'!$Y$9 -> 0.95 | M18: =F18*$F$6*H18*J18*12 -> 99750
D19: Keys & FOBs Replacement | F19: 50 | H19: 2 | J19: - | M19: =F19*H19*12 -> 1200
D20: Clubhouse Rental | F20: 250 | H20: 1 | J20: - | M20: =F20*H20*12 -> 3000
M21: =SUM(M8:M20) -> 399945
M23: =M21/$F$6/12 -> 95.225

Sheet Middle Payroll
A1: ='Middle Budget'!A1 -> 301 E. ATLANTIC POMPANO BEACH - PROJECTED STRIKE
B3: PRO FORMA PAYROLL
L4: Burden & OT | N4: Total Expense
F5: Annual Salary | H5: Bonus | J5: Total Comp. | L5: 0.3 | N5: Per FTE | P5: Full Time Equiv. | R5: Total Expense
D6: Property Manager | F6: 75000 | H6: =F6*0.1 -> 7500 | J6: =F6+H6 -> 82500 | L6: =J6*$L$5 -> 24750 | N6: =J6+L6 -> 107250 | P6: 1 | R6: =N6*P6 -> 107250
D7: Assistant Manager | F7: 60000 | H7: 0 | J7: =F7+H7 -> 60000 | L7: =J7*$L$5 -> 18000 | N7: =J7+L7 -> 78000 | P7: 1 | R7: =N7*P7 -> 78000
D8: Leasing Consultant | F8: 45000 | H8: 0 | J8: =F8+H8 -> 45000 | L8: =J8*$L$5 -> 13500 | N8: =J8+L8 -> 58500 | P8: 2 | R8: =N8*P8 -> 117000
D9: Supervisor | F9: 65000 | H9: =F9*0.1 -> 6500 | J9: =F9+H9 -> 71500 | L9: =J9*$L$5 -> 21450 | N9: =J9+L9 -> 92950 | P9: 1 | R9: =N9*P9 -> 92950
D10: Technician | F10: 55000 | H10: 0 | J10: =F10+H10 -> 55000 | L10: =J10*$L$5 -> 16500 | N10: =J10+L10 -> 71500 | P10: 2 | R10: =N10*P10 -> 143000
P11: =SUM(P6:P10) -> 7 | R11: =SUM(R6:R10) -> 538200
P13: =P11/('Middle Budget'!H11/50) -> 1 | R13: =R11/'Middle Budget'!H11 -> 1537.7143

Sheet Middle RETax
A1: ='Middle Budget'!A1 -> 301 E. ATLANTIC POMPANO BEACH - PROJECTED STRIKE
B5: PROPERTY TAX ESTIMATE AT COMPLETION UNDER DEVELOPER OWNERSHIP
E7: ='Middle Budget'!H24+1 -> 26 | G7: =LOOKUP(E7,'Middle ICF'!K3:EX3,'Middle ICF'!K35:EX35)*12 -> 12269132
E8: 0.1 | G8: =-E8*G7 -> -1226913.2
G9: =SUM(G7:G8) -> 11042219
E10: 0.4 | G10: =-E10*G9 -> -4416887.5
G11: =SUM(G9:G10) -> 6625331.3
D13: (a) | E13: County Appraiser Market Cap Rate | G13: 0.0525
E14: Tax Rate | G14: ='Middle Budget'!R12 -> 0.0205011
E15: County Appraiser Cap Rate | G15: =SUM(G13:G14) -> 0.0730011
E17: County Appraiser Gross Assessed Value | G17: =G11/G15 -> 90756595
E18: 0.15 | G18: =-$E$18*G17 -> -13613489
E19: Net Assessed Value | G19: =SUM(G17:G18) -> 77143106
E20: Tax Rate | G20: =G14 -> 0.0205011
E21: Tax Expense Before Early Payment Discount | G21: =G19*G20 -> 1581518.5
E22: 0.04 | G22: =-$E$22*G21 -> -63260.741
G23: =SUM(G21:G22) -> 1518257.8
F25: =G23/'Middle Budget'!$H$11 -> 4337.8794
D27: (a) | E27: County appraiser typically uses a cap rate above actual market cap rates for property tax assessment purposes.
B31: PROPERTY TAX ESTIMATE AT COMPLETION UNDER DEVELOPER OWNERSHIP - PERCENT OF COST
E33: Hard Costs | G33: ='Middle Budget'!L74 -> 82687500
E34: Reassessment as % of Total Cost | G34: 0.9
G35: =G33*G34 -> 74418750
E36: Tax Rate | G36: =G14 -> 0.0205011
G37: =G35*G36 -> 1525666.2
E38: =$E$22 -> 0.04 | G38: =G37*-E38 -> -61026.649
G39: =SUM(G37:G38) -> 1464639.6
F41: =G39/'Middle Budget'!$H$11 -> 4184.6845

Sheet Middle ICF
A1: ='Middle Budget'!A1 -> 301 E. ATLANTIC POMPANO BEACH - PROJECTED STRIKE
I3: Investment Period | J3: Closing | K3: 1 | L3: =K3+1 -> 2 | M3: =L3+1 -> 3 | N3: =M3+1 -> 4 | O3: =N3+1 -> 5 | P3: =O3+1 -> 6 | Q3: =P3+1 -> 7 | R3: =Q3+1 -> 8 | S3: =R3+1 -> 9 | ... EX3: =EW3+1 -> 144
I4: Date | J4: 46388 | K4: =EDATE(J4,1) -> 46419 | L4: =EDATE(K4,1) -> 46447 | M4: =EDATE(L4,1) -> 46478 | N4: =EDATE(M4,1) -> 46508 | O4: =EDATE(N4,1) -> 46539 | P4: =EDATE(O4,1) -> 46569 | Q4: =EDATE(P4,1) -> 46600 | R4: =EDATE(Q4,1) -> 46631 | ... EX4: =EDATE(EW4,1) -> 50771
I5: Year of Operations | K5: =IF(K3>=$C$14,ROUNDUP((K3-$C$14)/12,0),0) -> 0 | L5: =IF(L3>=$C$14,ROUNDUP((L3-$C$14)/12,0),0) -> 0 | M5: =IF(M3>=$C$14,ROUNDUP((M3-$C$14)/12,0),0) -> 0 | N5: =IF(N3>=$C$14,ROUNDUP((N3-$C$14)/12,0),0) -> 0 | O5: =IF(O3>=$C$14,ROUNDUP((O3-$C$14)/12,0),0) -> 0 | P5: =IF(P3>=$C$14,ROUNDUP((P3-$C$14)/12,0),0) -> 0 | Q5: =IF(Q3>=$C$14,ROUNDUP((Q3-$C$14)/12,0),0) -> 0 | R5: =IF(R3>=$C$14,ROUNDUP((R3-$C$14)/12,0),0) -> 0 | ... EX5: =IF(EX3>=$C$14,ROUNDUP((EX3-$C$14)/12,0),0) -> 10
I6: Status | K6: =IF(K3<$C$14,"Dev.",IF(AND(K3>=$C$14,K3<$C$16),"Lease-Up","Stabilized")) -> Dev. | L6: =IF(L3<$C$14,"Dev.",IF(AND(L3>=$C$14,L3<$C$16),"Lease-Up","Stabilized")) -> Dev. | M6: =IF(M3<$C$14,"Dev.",IF(AND(M3>=$C$14,M3<$C$16),"Lease-Up","Stabilized")) -> Dev. | N6: =IF(N3<$C$14,"Dev.",IF(AND(N3>=$C$14,N3<$C$16),"Lease-Up","Stabilized")) -> Dev. | O6: =IF(O3<$C$14,"Dev.",IF(AND(O3>=$C$14,O3<$C$16),"Lease-Up","Stabilized")) -> Dev. | P6: =IF(P3<$C$14,"Dev.",IF(AND(P3>=$C$14,P3<$C$16),"Lease-Up","Stabilized")) -> Dev. | Q6: =IF(Q3<$C$14,"Dev.",IF(AND(Q3>=$C$14,Q3<$C$16),"Lease-Up","Stabilized")) -> Dev. | R6: =IF(R3<$C$14,"Dev.",IF(AND(R3>=$C$14,R3<$C$16),"Lease-Up","Stabilized")) -> Dev. | ... EX6: =IF(EX3<$C$14,"Dev.",IF(AND(EX3>=$C$14,EX3<$C$16),"Lease-Up","Stabilized")) -> Stabilized
B8: Unit Count & Timing Summary (from Ops & SU tabs)
C9: ='Middle NOI'!F14 -> 350
C10: ='Middle Budget'!H20 -> 1
C11: ='Middle Budget'!H21 -> 24
C12: ='Middle Budget'!H22 -> 1
C13: ='Middle Budget'!H23 -> 26
C14: ='Middle Budget'!H24 -> 25
C15: ='Middle Budget'!H25 -> 25.576923
C16: ='Middle Budget'!H26 -> 37
C17: ='Middle Budget'!H27 -> 40
B19: UNIT OCCUPANCY & AVERAGE MONTHLY BASE RENT
C21: Occupied Units - Beginning | K21: 0 | L21: =K23 -> 0 | M21: =L23 -> 0 | N21: =M23 -> 0 | O21: =N23 -> 0 | P21: =O23 -> 0 | Q21: =P23 -> 0 | R21: =Q23 -> 0 | S21: =R23 -> 0 | ... EX21: =EW23 -> 332.5
C22: Move-ins | I22: =SUM(K22:EX22) -> 332.5 | K22: =IF(AND(K3>=$C$14,K3<=$C$16),$C$15,0) -> 0 | L22: =IF(AND(L3>=$C$14,L3<=$C$16),$C$15,0) -> 0 | M22: =IF(AND(M3>=$C$14,M3<=$C$16),$C$15,0) -> 0 | N22: =IF(AND(N3>=$C$14,N3<=$C$16),$C$15,0) -> 0 | O22: =IF(AND(O3>=$C$14,O3<=$C$16),$C$15,0) -> 0 | P22: =IF(AND(P3>=$C$14,P3<=$C$16),$C$15,0) -> 0 | Q22: =IF(AND(Q3>=$C$14,Q3<=$C$16),$C$15,0) -> 0 | R22: =IF(AND(R3>=$C$14,R3<=$C$16),$C$15,0) -> 0 | ... EX22: =IF(AND(EX3>=$C$14,EX3<=$C$16),$C$15,0) -> 0
C23: Occupied Units - Ending | I23: =I22/C9 -> 0.95 | K23: =SUM(K21:K22) -> 0 | L23: =SUM(L21:L22) -> 0 | M23: =SUM(M21:M22) -> 0 | N23: =SUM(N21:N22) -> 0 | O23: =SUM(O21:O22) -> 0 | P23: =SUM(P21:P22) -> 0 | Q23: =SUM(Q21:Q22) -> 0 | R23: =SUM(R21:R22) -> 0 | ... EX23: =SUM(EX21:EX22) -> 332.5
C24: Vacant Units | K24: =$C$9-K23 -> 350 | L24: =$C$9-L23 -> 350 | M24: =$C$9-M23 -> 350 | N24: =$C$9-N23 -> 350 | O24: =$C$9-O23 -> 350 | P24: =$C$9-P23 -> 350 | Q24: =$C$9-Q23 -> 350 | R24: =$C$9-R23 -> 350 | ... EX24: =$C$9-EX23 -> 17.5
C25: Total | K25: =SUM(K23:K24) -> 350 | L25: =SUM(L23:L24) -> 350 | M25: =SUM(M23:M24) -> 350 | N25: =SUM(N23:N24) -> 350 | O25: =SUM(O23:O24) -> 350 | P25: =SUM(P23:P24) -> 350 | Q25: =SUM(Q23:Q24) -> 350 | R25: =SUM(R23:R24) -> 350 | ... EX25: =SUM(EX23:EX24) -> 350
J27: Occupancy: | K27: =K23/$C$9 -> 0 | L27: =L23/$C$9 -> 0 | M27: =M23/$C$9 -> 0 | N27: =N23/$C$9 -> 0 | O27: =O23/$C$9 -> 0 | P27: =P23/$C$9 -> 0 | Q27: =Q23/$C$9 -> 0 | R27: =R23/$C$9 -> 0 | ... EX27: =EX23/$C$9 -> 0.95
J28: Avg. Base Rent: | K28: =IF(K27>0,K35/$C$9,0) -> 0 | L28: =IF(L27>0,L35/$C$9,0) -> 0 | M28: =IF(M27>0,M35/$C$9,0) -> 0 | N28: =IF(N27>0,N35/$C$9,0) -> 0 | O28: =IF(O27>0,O35/$C$9,0) -> 0 | P28: =IF(P27>0,P35/$C$9,0) -> 0 | Q28: =IF(Q27>0,Q35/$C$9,0) -> 0 | R28: =IF(R27>0,R35/$C$9,0) -> 0 | ... EX28: =IF(EX27>0,EX35/$C$9,0) -> 3906.5848
B30: OPERATING INCOME
F32: From Ops Tab
B33: Income | G33: Stabilized
F34: Untrended | G34: Assumptions
C35: Market Rent | F35: ='Middle NOI'!K33 -> 11508000 | G35: ='Middle NOI'!$Y$7 -> 0.03 | K35: =IF(K$5>0,($F35/12)*(1+((1+$G35)^(1/12))-1)^K$3,0) -> 0 | L35: =IF(L$5>0,($F35/12)*(1+((1+$G35)^(1/12))-1)^L$3,0) -> 0 | M35: =IF(M$5>0,($F35/12)*(1+((1+$G35)^(1/12))-1)^M$3,0) -> 0 | N35: =IF(N$5>0,($F35/12)*(1+((1+$G35)^(1/12))-1)^N$3,0) -> 0 | O35: =IF(O$5>0,($F35/12)*(1+((1+$G35)^(1/12))-1)^O$3,0) -> 0 | P35: =IF(P$5>0,($F35/12)*(1+((1+$G35)^(1/12))-1)^P$3,0) -> 0 | Q35: =IF(Q$5>0,($F35/12)*(1+((1+$G35)^(1/12))-1)^Q$3,0) -> 0 | R35: =IF(R$5>0,($F35/12)*(1+((1+$G35)^(1/12))-1)^R$3,0) -> 0 | ... EX35: =IF(EX$5>0,($F35/12)*(1+((1+$G35)^(1/12))-1)^EX$3,0) -> 1367304.7
C36: Loss to Lease (starts at stabilization) | F36: ='Middle NOI'!K34 -> 0 | G36: ='Middle NOI'!Y8 -> 0.01 | K36: =IF(K$35=0,0,IF(K$27<(1-$G$39),0,K$35*-$G36)) -> 0 | L36: =IF(L$35=0,0,IF(L$27<(1-$G$39),0,L$35*-$G36)) -> 0 | M36: =IF(M$35=0,0,IF(M$27<(1-$G$39),0,M$35*-$G36)) -> 0 | N36: =IF(N$35=0,0,IF(N$27<(1-$G$39),0,N$35*-$G36)) -> 0 | O36: =IF(O$35=0,0,IF(O$27<(1-$G$39),0,O$35*-$G36)) -> 0 | P36: =IF(P$35=0,0,IF(P$27<(1-$G$39),0,P$35*-$G36)) -> 0 | Q36: =IF(Q$35=0,0,IF(Q$27<(1-$G$39),0,Q$35*-$G36)) -> 0 | R36: =IF(R$35=0,0,IF(R$27<(1-$G$39),0,R$35*-$G36)) -> 0 | ... EX36: =IF(EX$35=0,0,IF(EX$27<(1-$G$39),0,EX$35*-$G36)) -> -13673.047
C37: Gross Potential Rent | F37: =SUM(F35:F36) -> 11508000 | K37: =SUM(K35:K36) -> 0 | L37: =SUM(L35:L36) -> 0 | M37: =SUM(M35:M36) -> 0 | N37: =SUM(N35:N36) -> 0 | O37: =SUM(O35:O36) -> 0 | P37: =SUM(P35:P36) -> 0 | Q37: =SUM(Q35:Q36) -> 0 | R37: =SUM(R35:R36) -> 0 | ... EX37: =SUM(EX35:EX36) -> 1353631.6
C39: Vacancy | F39: ='Middle NOI'!K37 -> -575400 | G39: ='Middle NOI'!Y9 -> 0.05 | K39: =IF(K$35=0,0,-K$35*(1-K$27)) -> 0 | L39: =IF(L$35=0,0,-L$35*(1-L$27)) -> 0 | M39: =IF(M$35=0,0,-M$35*(1-M$27)) -> 0 | N39: =IF(N$35=0,0,-N$35*(1-N$27)) -> 0 | O39: =IF(O$35=0,0,-O$35*(1-O$27)) -> 0 | P39: =IF(P$35=0,0,-P$35*(1-P$27)) -> 0 | Q39: =IF(Q$35=0,0,-Q$35*(1-Q$27)) -> 0 | R39: =IF(R$35=0,0,-R$35*(1-R$27)) -> 0 | ... EX39: =IF(EX$35=0,0,-EX$35*(1-EX$27)) -> -68365.235
C40: Collection Loss | F40: ='Middle NOI'!K38 -> -28770 | G40: ='Middle NOI'!Y10 -> 0.0025 | K40: =IF(K$37=0,0,-K$37*$G40) -> 0 | L40: =IF(L$37=0,0,-L$37*$G40) -> 0 | M40: =IF(M$37=0,0,-M$37*$G40) -> 0 | N40: =IF(N$37=0,0,-N$37*$G40) -> 0 | O40: =IF(O$37=0,0,-O$37*$G40) -> 0 | P40: =IF(P$37=0,0,-P$37*$G40) -> 0 | Q40: =IF(Q$37=0,0,-Q$37*$G40) -> 0 | R40: =IF(R$37=0,0,-R$37*$G40) -> 0 | ... EX40: =IF(EX$37=0,0,-EX$37*$G40) -> -3384.0791
C41: Net Rental Income | F41: =F37+F39+F40 -> 10903830 | K41: =K37+K39+K40 -> 0 | L41: =L37+L39+L40 -> 0 | M41: =M37+M39+M40 -> 0 | N41: =N37+N39+N40 -> 0 | O41: =O37+O39+O40 -> 0 | P41: =P37+P39+P40 -> 0 | Q41: =Q37+Q39+Q40 -> 0 | R41: =R37+R39+R40 -> 0 | ... EX41: =EX37+EX39+EX40 -> 1281882.3
C42: RUBS Income | F42: ='Middle NOI'!K40 -> 280000 | G42: ='Middle NOI'!E40 -> 0.8 | H42: Variable % utilities expense | K42: =$G$42*K53 -> 0 | L42: =$G$42*L53 -> 0 | M42: =$G$42*M53 -> 0 | N42: =$G$42*N53 -> 0 | O42: =$G$42*O53 -> 0 | P42: =$G$42*P53 -> 0 | Q42: =$G$42*Q53 -> 0 | R42: =$G$42*R53 -> 0 | ... EX42: =$G$42*EX53 -> 31380.739
C43: Other Income | F43: ='Middle NOI'!K41 -> 399945 | G43: ='Middle NOI'!$Y$7 -> 0.03 | H43: Variable occupancy | K43: =IF(K27<(1-$G$39),(($F43/12)*(1+((1+$G43)^(1/12))-1)^K$3)*K27,($F43/12)*(1+((1+$G43)^(1/12))-1)^K$3) -> 0 | L43: =IF(L27<(1-$G$39),(($F43/12)*(1+((1+$G43)^(1/12))-1)^L$3)*L27,($F43/12)*(1+((1+$G43)^(1/12))-1)^L$3) -> 0 | M43: =IF(M27<(1-$G$39),(($F43/12)*(1+((1+$G43)^(1/12))-1)^M$3)*M27,($F43/12)*(1+((1+$G43)^(1/12))-1)^M$3) -> 0 | N43: =IF(N27<(1-$G$39),(($F43/12)*(1+((1+$G43)^(1/12))-1)^N$3)*N27,($F43/12)*(1+((1+$G43)^(1/12))-1)^N$3) -> 0 | O43: =IF(O27<(1-$G$39),(($F43/12)*(1+((1+$G43)^(1/12))-1)^O$3)*O27,($F43/12)*(1+((1+$G43)^(1/12))-1)^O$3) -> 0 | P43: =IF(P27<(1-$G$39),(($F43/12)*(1+((1+$G43)^(1/12))-1)^P$3)*P27,($F43/12)*(1+((1+$G43)^(1/12))-1)^P$3) -> 0 | Q43: =IF(Q27<(1-$G$39),(($F43/12)*(1+((1+$G43)^(1/12))-1)^Q$3)*Q27,($F43/12)*(1+((1+$G43)^(1/12))-1)^Q$3) -> 0 | R43: =IF(R27<(1-$G$39),(($F43/12)*(1+((1+$G43)^(1/12))-1)^R$3)*R27,($F43/12)*(1+((1+$G43)^(1/12))-1)^R$3) -> 0 | ... EX43: =IF(EX27<(1-$G$39),(($F43/12)*(1+((1+$G43)^(1/12))-1)^EX$3)*EX27,($F43/12)*(1+((1+$G43)^(1/12))-1)^EX$3) -> 47518.828
C44: Total Revenue | F44: =SUM(F41:F43) -> 11583775 | K44: =SUM(K41:K43) -> 0 | L44: =SUM(L41:L43) -> 0 | M44: =SUM(M41:M43) -> 0 | N44: =SUM(N41:N43) -> 0 | O44: =SUM(O41:O43) -> 0 | P44: =SUM(P41:P43) -> 0 | Q44: =SUM(Q41:Q43) -> 0 | R44: =SUM(R41:R43) -> 0 | ... EX44: =SUM(EX41:EX43) -> 1360781.9
B46: Operating Expenses
C48: Payroll | F48: ='Middle NOI'!K46 -> 538200 | G48: ='Middle NOI'!$Y$11 -> 0.025 | H48: Fixed | K48: =IF(K$5>0,($F48/12)*(1+((1+$G48)^(1/12))-1)^K$3,0) -> 0 | L48: =IF(L$5>0,($F48/12)*(1+((1+$G48)^(1/12))-1)^L$3,0) -> 0 | M48: =IF(M$5>0,($F48/12)*(1+((1+$G48)^(1/12))-1)^M$3,0) -> 0 | N48: =IF(N$5>0,($F48/12)*(1+((1+$G48)^(1/12))-1)^N$3,0) -> 0 | O48: =IF(O$5>0,($F48/12)*(1+((1+$G48)^(1/12))-1)^O$3,0) -> 0 | P48: =IF(P$5>0,($F48/12)*(1+((1+$G48)^(1/12))-1)^P$3,0) -> 0 | Q48: =IF(Q$5>0,($F48/12)*(1+((1+$G48)^(1/12))-1)^Q$3,0) -> 0 | R48: =IF(R$5>0,($F48/12)*(1+((1+$G48)^(1/12))-1)^R$3,0) -> 0 | ... EX48: =IF(EX$5>0,($F48/12)*(1+((1+$G48)^(1/12))-1)^EX$3,0) -> 60318.264
C49: General & Administrative | F49: ='Middle NOI'!K47 -> 87500 | G49: ='Middle NOI'!$Y$11 -> 0.025 | H49: Fixed | K49: =IF(K$5>0,($F49/12)*(1+((1+$G49)^(1/12))-1)^K$3,0) -> 0 | L49: =IF(L$5>0,($F49/12)*(1+((1+$G49)^(1/12))-1)^L$3,0) -> 0 | M49: =IF(M$5>0,($F49/12)*(1+((1+$G49)^(1/12))-1)^M$3,0) -> 0 | N49: =IF(N$5>0,($F49/12)*(1+((1+$G49)^(1/12))-1)^N$3,0) -> 0 | O49: =IF(O$5>0,($F49/12)*(1+((1+$G49)^(1/12))-1)^O$3,0) -> 0 | P49: =IF(P$5>0,($F49/12)*(1+((1+$G49)^(1/12))-1)^P$3,0) -> 0 | Q49: =IF(Q$5>0,($F49/12)*(1+((1+$G49)^(1/12))-1)^Q$3,0) -> 0 | R49: =IF(R$5>0,($F49/12)*(1+((1+$G49)^(1/12))-1)^R$3,0) -> 0 | ... EX49: =IF(EX$5>0,($F49/12)*(1+((1+$G49)^(1/12))-1)^EX$3,0) -> 9806.481
C50: Repairs & Maintenance | F50: ='Middle NOI'!K48 -> 87500 | G50: ='Middle NOI'!$Y$11 -> 0.025 | H50: Fixed post-stabilization | K50: =IF(K$27<(1-$G$39),0,($F50/12)*(1+((1+$G50)^(1/12))-1)^K$3) -> 0 | L50: =IF(L$27<(1-$G$39),0,($F50/12)*(1+((1+$G50)^(1/12))-1)^L$3) -> 0 | M50: =IF(M$27<(1-$G$39),0,($F50/12)*(1+((1+$G50)^(1/12))-1)^M$3) -> 0 | N50: =IF(N$27<(1-$G$39),0,($F50/12)*(1+((1+$G50)^(1/12))-1)^N$3) -> 0 | O50: =IF(O$27<(1-$G$39),0,($F50/12)*(1+((1+$G50)^(1/12))-1)^O$3) -> 0 | P50: =IF(P$27<(1-$G$39),0,($F50/12)*(1+((1+$G50)^(1/12))-1)^P$3) -> 0 | Q50: =IF(Q$27<(1-$G$39),0,($F50/12)*(1+((1+$G50)^(1/12))-1)^Q$3) -> 0 | R50: =IF(R$27<(1-$G$39),0,($F50/12)*(1+((1+$G50)^(1/12))-1)^R$3) -> 0 | ... EX50: =IF(EX$27<(1-$G$39),0,($F50/12)*(1+((1+$G50)^(1/12))-1)^EX$3) -> 9806.481
...

Sheet Low Budget
A1: =Summary!$A$1&" - "&Summary!$G$4 -> 301 E. ATLANTIC POMPANO BEACH - BUYER'S PREFERRED | Z1: FONT KEY
Z2: Blue = Input cell
Z3: Red = Link to Summary
C4: UNIT SUMMARY | L4: PROJECTED PROFIT ON SALE AT STABILIZATION | Z4: Orange = Link to Middle scenario
Z5: Black = Text or formula cell
E6: Development Land Area | H6: ='Middle Budget'!H6 -> 2.3362029
E7: Density | H7: =H11/H6 -> 149.81575 | L7: Stabilized Value | T7: Sale / Refi | V7: Stabilization
E8: Height | H8: ='Middle Budget'!H8 -> 8 | T8: =H27 -> 40 | V8: =H26 -> 37
E9: Gross Building Area | H9: =H12/H10 -> 525000 | L9: NOI with Developer Property Taxes | R9: RE Tax | T9: =LOOKUP(H27,'Low ICF'!K3:EX3,'Low ICF'!K61:EX61)*12 -> 8480558.3 | V9: =LOOKUP(H26,'Low ICF'!K3:EX3,'Low ICF'!K61:EX61)*12 -> 8413315.5
E10: Building Efficiency | H10: ='Middle Budget'!H10 -> 0.5 | L10: Add Back: Developer Property Taxes | R10: Reassessment | T10: =LOOKUP(H27,'Low ICF'!K3:EX3,'Low ICF'!K57:EX57)*12 -> 1648510.6 | V10: =LOOKUP(H26,'Low ICF'!K3:EX3,'Low ICF'!K57:EX57)*12 -> 1638365.4
E11: Unit Count - Total | H11: ='Low NOI'!F14 -> 350 | L11: Less: Taxes with Market Value Reassessment | R11: ='Middle Budget'!R11 -> 0.75 | T11: =-T14*$R$11*$R$12*(1-R13) -> -2401400.2 | V11: =-V14*R11*R12*(1-R13) -> -2383053.1
E12: Net Rentable Area | H12: ='Low NOI'!I14 -> 262500 | L12: NOI After Market Value Tax Reassessment | R12: ='Middle Budget'!R12 -> 0.0205011 | T12: =SUM(T9:T11) -> 7727668.7 | V12: =SUM(V9:V11) -> 7668627.8
E13: Average Unit Size | H13: =H12/H11 -> 750 | L13: Market Cap Rate | R13: ='Middle Budget'!R13 -> 0.04 | T13: =Summary!G32 -> 0.0475 | V13: =Summary!G32 -> 0.0475
E14: Un-Trended Average Rent Per Unit | H14: ='Low NOI'!K14 -> 2740 | L14: Estimated Market Value | T14: =IF(ABS(T13)>0,T12/T13,0) -> 1.6268776e+08 | V14: =IF(ABS(V13)>0,V12/V13,0) -> 1.614448e+08
E15: Un-Trended Average Rent Per SF | H15: ='Low NOI'!M14 -> 3.6533333
E16: Un-Trended NOI (developer property taxes) | H16: ='Low NOI'!K62 -> 7738141.7 | L16: Net Profit on Sale at Stabilization
R17: Total | T17: Per Unit | V17: Per SF
C18: PROJECTED TIMING | L18: Value at Sale Date | R18: =T14 -> 1.6268776e+08 | T18: =R18/$H$11 -> 464822.17 | V18: =R18/$H$12 -> 619.7629
L19: ='Middle Budget'!L19 -> 0.0125 | M19: ='Middle Budget'!M19 -> 0 | N19: ='Middle Budget'!N19 -> 0 | O19: ='Middle Budget'!O19 -> 0 | P19: ='Middle Budget'!P19 -> 0 | R19: =R18*-L19 -> -2033597 | T19: =R19/$H$11 -> -5810.2772 | V19: =R19/$H$12 -> -7.7470362
E20: Hard Cost Draws Start | H20: ='Middle Budget'!H20 -> 1 | L20: Net Sale Proceeds | R20: =SUM(R18:R19) -> 1.6065416e+08 | T20: =R20/$H$11 -> 459011.9 | V20: =R20/$H$12 -> 612.01586
E21: Hard Cost Draws End | H21: =Summary!G42 -> 24 | L21: Less: Total Land & Development Cost | R21: =-L110 -> -1.1795428e+08 | T21: =R21/$H$11 -> -337012.23 | V21: =R21/$H$12 -> -449.34963
E22: Soft Cost Draws Start Excl. Op. Deficit | H22: ='Middle Budget'!H22 -> 1 | L22: Net Profit on Sale | R22: =SUM(R20:R21) -> 42699885 | T22: =R22/$H$11 -> 121999.67 | V22: =R22/$H$12 -> 162.66623
E23: ='Middle Budget'!E23 -> 2 | H23: =H21+E23 -> 26 | L23: Add: Operating Cash Flow After Debt Service | R23: ='Low ICF'!I104-'Low ICF'!I115 -> 2244685.6 | T23: =R23/$H$11 -> 6413.3874 | V23: =R23/$H$12 -> 8.5511832
E24: ='Middle Budget'!E24 -> 1 | H24: =H21+E24 -> 25 | L24: Total Net Profit | R24: =SUM(R22:R23) -> 44944570 | T24: =R24/$H$11 -> 128413.06 | V24: =R24/$H$12 -> 171.21741
E25: Average Monthly Move-Ins | H25: =(H11*(1-'Low NOI'!$Y$9))/(H26-H24+1) -> 25.576923
E26: =Summary!G31 -> 12 | H26: =H24+E26 -> 37 | L26: RETURN METRICS
E27: ='Middle Budget'!E27 -> 3 | H27: =H26+E27 -> 40
L28: Merchant Build
C29: CONSTRUCTION FINANCING ASSUMPTIONS | L29: Untrended Return on Cost (NOI with developer property taxes) | V29: =H16/L110 -> 0.065602891
L30: Net Profit as % of Cost (excl. net op. CF) | V30: =IF(ABS(R21)>0,-R22/R21,0) -> 0.3620037
E31: Maximum Loan to Cost | H31: ='Middle Budget'!H31 -> 0.65 | L31: IRR on Sale at Stabilization (incl. net op. CF) | V31: ='Low ICF'!F110 -> 0.24813606
E32: Maximum % of Stabilized Value | H32: ='Middle Budget'!H32 -> 0.55 | L32: Equity Multiple on Sale at Stabilization (incl. net op. CF) | V32: =(R24+L49)/L49 -> 2.0922063
E33: Minimum Un-Trended Debt Yield (NOI with developer property taxes) | H33: ='Middle Budget'!H33 -> 0.085
E34: Interest Rate - Projected Average Index | H34: ='Middle Budget'!H34 -> 0.035 | L34: Permanent Refinancing
E35: Interest Rate - Spread | H35: ='Middle Budget'!H35 -> 0.025 | L35: Post-Permanent Refinancing Cash-on-Cash Return - Interest Only | V35: =L155 -> 0.14069565
E36: Interest Rate - Total | H36: =H34+H35 -> 0.06 | L36: Post-Permanent Refinancing Cash-on-Cash Return - Amortizing | V36: =H155 -> 0.082007948
E37: Minimum Interest - Months | H37: ='Middle Budget'!H37 -> 12
E38: Minimum Interest - Amount | H38: =L48*H36/12*H37 -> 4585314.6
E39: Origination Fee | H39: ='Middle Budget'!H39 -> 0.01
E40: Exit Fee | H40: ='Middle Budget'!H40 -> 0.005
...

Sheet Low NOI
A1: ='Low Budget'!A1 -> 301 E. ATLANTIC POMPANO BEACH - BUYER'S PREFERRED
B5: UNIT MIX & MARKET RENT | R5: OPERATING ASSUMPTIONS
K6: Untrended Rent
S7: Annual Rent & Other Income Growth | Y7: ='Middle NOI'!Y7 -> 0.03
F8: Units | G8: % Units | H8: Avg. SF | I8: Total SF | K8: Per Unit | M8: Per SF | O8: Total $ | S8: Loss-to-Lease (% of market rent) | Y8: ='Middle NOI'!Y8 -> 0.01
S9: Stabilized Vacancy (% of market rent) | Y9: ='Middle NOI'!Y9 -> 0.05
E10: Studio | F10: ='Middle NOI'!F10 -> 70 | G10: =F10/$F$14 -> 0.2 | H10: ='Middle NOI'!H10 -> 500 | I10: =F10*H10 -> 35000 | K10: =Summary!G25 -> 2100 | M10: =O10/I10 -> 4.2 | O10: =F10*K10 -> 147000 | S10: Collection Loss (% of GPR) | Y10: ='Middle NOI'!Y10 -> 0.0025
E11: One Bedroom | F11: ='Middle NOI'!F11 -> 140 | G11: =F11/$F$14 -> 0.4 | H11: ='Middle NOI'!H11 -> 675 | I11: =F11*H11 -> 94500 | K11: =Summary!I25 -> 2650 | M11: =O11/I11 -> 3.9259259 | O11: =F11*K11 -> 371000 | S11: Annual Operating Expense Growth | Y11: ='Middle NOI'!Y11 -> 0.025
E12: Two Bedroom | F12: ='Middle NOI'!F12 -> 140 | G12: =F12/$F$14 -> 0.4 | H12: ='Middle NOI'!H12 -> 950 | I12: =F12*H12 -> 133000 | K12: =Summary!K25 -> 3150 | M12: =O12/I12 -> 3.3157895 | O12: =F12*K12 -> 441000 | S12: ='Middle NOI'!S12 -> 0.75 | T12: ='Middle NOI'!T12 -> 0 | U12: ='Middle NOI'!U12 -> 0 | V12: ='Middle NOI'!V12 -> 0 | W12: ='Middle NOI'!W12 -> 0 | Y12: ='Middle NOI'!Y12 -> 0.25
S13: Management Fee (% of total revenue) | Y13: ='Middle NOI'!Y13 -> 0.02
F14: =SUM(F10:F13) -> 350 | G14: =SUM(G10:G13) -> 1 | H14: =I14/F14 -> 750 | I14: =SUM(I10:I13) -> 262500 | K14: =O14/F14 -> 2740 | M14: =O14/I14 -> 3.6533333 | O14: =SUM(O10:O13) -> 959000 | S14: Management Fee Monthly Minimum Until Stabilization | Y14: ='Middle NOI'!Y14 -> 5000
S15: Replacement Reserve Per Unit Annually | Y15: ='Middle NOI'!Y15 -> 200
S19: Year of Operations
B20: PROJECTED OPERATING RESULTS | S20: 1 | U20: 2 | W20: 3 | Y20: 4 | AA20: 5
S21: =LOOKUP('Low ICF'!$C$14,'Low ICF'!$K$3:$EX$3,'Low ICF'!$K$6:$EX$6) -> Lease-Up | U21: =LOOKUP('Low ICF'!$C$14+12,'Low ICF'!$K$3:$EX$3,'Low ICF'!$K$6:$EX$6) -> Stabilized | W21: =LOOKUP('Low ICF'!$C$14+24,'Low ICF'!$K$3:$EX$3,'Low ICF'!$K$6:$EX$6) -> Stabilized | Y21: =LOOKUP('Low ICF'!$C$14+36,'Low ICF'!$K$3:$EX$3,'Low ICF'!$K$6:$EX$6) -> Stabilized | AA21: =LOOKUP('Low ICF'!$C$14+48,'Low ICF'!$K$3:$EX$3,'Low ICF'!$K$6:$EX$6) -> Stabilized
R23: Beginning Avg. Monthly Rent: | S23: =LOOKUP('Low ICF'!$C$14+1,'Low ICF'!$K$3:$EX$3,'Low ICF'!$K$28:$EX$28) -> 2921.2219 | U23: =LOOKUP('Low ICF'!$C$14+1+12,'Low ICF'!$K$3:$EX$3,'Low ICF'!$K$28:$EX$28) -> 3008.8586 | W23: =LOOKUP('Low ICF'!$C$14+1+24,'Low ICF'!$K$3:$EX$3,'Low ICF'!$K$28:$EX$28) -> 3099.1243 | Y23: =LOOKUP('Low ICF'!$C$14+1+36,'Low ICF'!$K$3:$EX$3,'Low ICF'!$K$28:$EX$28) -> 3192.0981 | AA23: =LOOKUP('Low ICF'!$C$14+1+48,'Low ICF'!$K$3:$EX$3,'Low ICF'!$K$28:$EX$28) -> 3287.861
R24: Ending Avg. Monthly Rent: | S24: =LOOKUP('Low ICF'!$C$14+12,'Low ICF'!$K$3:$EX$3,'Low ICF'!$K$28:$EX$28) -> 3001.4562 | U24: =LOOKUP('Low ICF'!$C$14+12+12,'Low ICF'!$K$3:$EX$3,'Low ICF'!$K$28:$EX$28) -> 3091.4999 | W24: =LOOKUP('Low ICF'!$C$14+12+24,'Low ICF'!$K$3:$EX$3,'Low ICF'!$K$28:$EX$28) -> 3184.2448 | Y24: =LOOKUP('Low ICF'!$C$14+12+36,'Low ICF'!$K$3:$EX$3,'Low ICF'!$K$28:$EX$28) -> 3279.7722 | AA24: =LOOKUP('Low ICF'!$C$14+12+48,'Low ICF'!$K$3:$EX$3,'Low ICF'!$K$28:$EX$28) -> 3378.1654
R25: Rent Growth % (begin to begin): | S25: 0 | U25: =(U23-S23)/S23 -> 0.03 | W25: =(W23-U23)/U23 -> 0.03 | Y25: =(Y23-W23)/W23 -> 0.03 | AA25: =(AA23-Y23)/Y23 -> 0.03
R26: Average Vacancy: | S26: =-S37/S33 -> 0.44977804 | U26: =-U37/U33 -> 0.05 | W26: =-W37/W33 -> 0.05 | Y26: =-Y37/Y33 -> 0.05 | AA26: =-AA37/AA33 -> 0.05
R27: NOI as % of Market Rent: | S27: =S62/S33 -> 0.3437779 | U27: =U62/U33 -> 0.64432249 | W27: =W62/W33 -> 0.64595275 | Y27: =Y62/Y33 -> 0.64757123 | AA27: =AA62/AA33 -> 0.6491781
R28: NOI Growth: | S28: 0 | U28: =(U62-S62)/S62 -> 0.93046781 | W28: =(W62-U62)/U62 -> 0.032606093 | Y28: =(Y62-W62)/W62 -> 0.032580737 | AA28: =(AA62-Y62)/Y62 -> 0.032555825
K30: Untrended
C31: Income | K31: Total | M31: Per Unit | O31: % Mkt
E33: Market Rent | K33: =F14*K14*12 -> 11508000 | M33: =K33/$F$14 -> 32880 | O33: =K33/K$33 -> 1 | S33: =SUMIF('Low ICF'!$K$5:$EX$5,S$20,'Low ICF'!$K35:$EX35) -> 12436932 | U33: =SUMIF('Low ICF'!$K$5:$EX$5,U$20,'Low ICF'!$K35:$EX35) -> 12810040 | W33: =SUMIF('Low ICF'!$K$5:$EX$5,W$20,'Low ICF'!$K35:$EX35) -> 13194341 | Y33: =SUMIF('Low ICF'!$K$5:$EX$5,Y$20,'Low ICF'!$K35:$EX35) -> 13590172 | AA33: =SUMIF('Low ICF'!$K$5:$EX$5,AA$20,'Low ICF'!$K35:$EX35) -> 13997877
D34: (a) | E34: Loss-to-Lease | K34: 0 | M34: =K34/$F$14 -> 0 | O34: =K34/K$33 -> 0 | S34: =SUMIF('Low ICF'!$K$5:$EX$5,S$20,'Low ICF'!$K36:$EX36) -> -10505.097 | U34: =SUMIF('Low ICF'!$K$5:$EX$5,U$20,'Low ICF'!$K36:$EX36) -> -128100.4 | W34: =SUMIF('Low ICF'!$K$5:$EX$5,W$20,'Low ICF'!$K36:$EX36) -> -131943.41 | Y34: =SUMIF('Low ICF'!$K$5:$EX$5,Y$20,'Low ICF'!$K36:$EX36) -> -135901.72 | AA34: =SUMIF('Low ICF'!$K$5:$EX$5,AA$20,'Low ICF'!$K36:$EX36) -> -139978.77
E35: Gross Potential Rent | K35: =SUM(K33:K34) -> 11508000 | M35: =K35/$F$14 -> 32880 | O35: =K35/K$33 -> 1 | S35: =SUM(S33:S34) -> 12426427 | U35: =SUM(U33:U34) -> 12681940 | W35: =SUM(W33:W34) -> 13062398 | Y35: =SUM(Y33:Y34) -> 13454270 | AA35: =SUM(AA33:AA34) -> 13857898
E37: Vacancy | K37: =-K33*$Y9 -> -575400 | M37: =K37/$F$14 -> -1644 | O37: =K37/K$33 -> -0.05 | S37: =SUMIF('Low ICF'!$K$5:$EX$5,S$20,'Low ICF'!$K39:$EX39) -> -5593859 | U37: =SUMIF('Low ICF'!$K$5:$EX$5,U$20,'Low ICF'!$K39:$EX39) -> -640502.01 | W37: =SUMIF('Low ICF'!$K$5:$EX$5,W$20,'Low ICF'!$K39:$EX39) -> -659717.07 | Y37: =SUMIF('Low ICF'!$K$5:$EX$5,Y$20,'Low ICF'!$K39:$EX39) -> -679508.58 | AA37: =SUMIF('Low ICF'!$K$5:$EX$5,AA$20,'Low ICF'!$K39:$EX39) -> -699893.84
