Workbook
Name \a: #N/A
Name \C: #REF!
Name \E: #REF!
Name \L: #REF!
Name \m: #N/A
Name \P: #REF!
Name \Q: #REF!
Name \r: #REF!
Name \s: #REF!
Name \t: #REF!
Name \z: #N/A
Name _1: #REF!
Name _10: #REF!
Name _11: #REF!
Name _18WDCART: #N/A
Name _18WDFEE: #N/A
Name _18WECART: #N/A
Name _18WEFEE: #N/A
Name _2: #REF!
Name _3: #REF!
Name _4: #REF!
Name _5: #REF!
Name _6: #REF!
Name _7: #REF!
Name _8: #REF!
Name _9: #REF!
Name _9WDCART: #N/A
Name _9WDFEE: #N/A
Name _9WECART: #N/A
Name _9WEFEE: #N/A
Name _DLC141: #REF!
Name _Res1: #REF!
Name _SPL2: #REF!
Name _SPL3: #REF!
Name _Vst1: #REF!
Name a_1: #REF!
Name AACT: #REF!
Name AACTYTD: #REF!
Name AB_1: #REF!
Name AB_1: #REF!
Name AB_1: #REF!
Name AB_10: #REF!
Name AB_10: #REF!
Name AB_10: #REF!
Name AB_11: #REF!
Name AB_11: #REF!
Name AB_11: #REF!
Name AB_12: #REF!
Name AB_12: #REF!
Name AB_12: #REF!
Name AB_2: #REF!
Name AB_2: #REF!
Name AB_2: #REF!
Name AB_3: #REF!
Name AB_3: #REF!
Name AB_3: #REF!
Name AB_4: #REF!
Name AB_4: #REF!
Name AB_4: #REF!
Name AB_5: #REF!

Sheet Summary
B2: =+P_L!B2 -> Sentosa Epperson
B3: =+P_L!P2 -> Wesley Chapel, FL
B4: =+Detail!D67 -> 288 | S4: 45657
B5: =+Detail!G67 -> 294000
G6: Stabilized | J6: 1 | K6: =J6+1 -> 2 | L6: =K6+1 -> 3 | M6: =L6+1 -> 4 | N6: =M6+1 -> 5 | O6: =N6+1 -> 6 | P6: =O6+1 -> 7 | Q6: =P6+1 -> 8 | R6: =Q6+1 -> 9 | S6: =R6+1 -> 10
B7: Capitalization
B8: Purchase Cap Rate | C8: =Detail!M37 -> 0.057026737 | F8: Rent/Unit/Month | G8: =+Detail!H67 -> 1910.296 | J8: =J11/Detail!$C$8/12 -> 1916.2857 | K8: =K11/Detail!$C$8/12 -> 1966.0167 | L8: =L11/Detail!$C$8/12 -> 2025.8149 | M8: =M11/Detail!$C$8/12 -> 2087.432 | N8: =N11/Detail!$C$8/12 -> 2150.9233 | O8: =O11/Detail!$C$8/12 -> 2216.3457 | P8: =P11/Detail!$C$8/12 -> 2283.7579 | Q8: =Q11/Detail!$C$8/12 -> 2353.2206 | ... S8: =S11/Detail!$C$8/12 -> 2498.5486
B9: Purchase Price | C9: =Detail!H25 -> 71029066 | D9: =C9/$B$4 -> 246628.7 | F9: Rent/SF/Mnth | G9: =+Detail!I67 -> 1.8713104 | J9: =J8/Detail!$F$67 -> 1.8771778 | K9: =K8/Detail!$F$67 -> 1.9258939 | L9: =L8/Detail!$F$67 -> 1.9844718 | M9: =M8/Detail!$F$67 -> 2.0448314 | N9: =N8/Detail!$F$67 -> 2.1070269 | O9: =O8/Detail!$F$67 -> 2.1711141 | P9: =P8/Detail!$F$67 -> 2.2371506 | Q9: =Q8/Detail!$F$67 -> 2.3051957 | ... S9: =S8/Detail!$F$67 -> 2.4475578
B10: Closing Costs | C10: =Detail!H27 -> 0 | H10: % of GPR
B11: Total Costs | C11: =Detail!H28 -> 71029066 | F11: Gross Potential Rent | G11: =+P_L!E10 -> 6601983.1 | J11: =SUMIF('Cash Flow'!$E$13:$FS$13,J$6,'Cash Flow'!$E$39:$FS$39) -> 6622683.2 | K11: =SUMIF('Cash Flow'!$E$13:$FS$13,K$6,'Cash Flow'!$E$39:$FS$39) -> 6794553.6 | L11: =SUMIF('Cash Flow'!$E$13:$FS$13,L$6,'Cash Flow'!$E$39:$FS$39) -> 7001216.4 | M11: =SUMIF('Cash Flow'!$E$13:$FS$13,M$6,'Cash Flow'!$E$39:$FS$39) -> 7214165.1 | N11: =SUMIF('Cash Flow'!$E$13:$FS$13,N$6,'Cash Flow'!$E$39:$FS$39) -> 7433590.8 | O11: =SUMIF('Cash Flow'!$E$13:$FS$13,O$6,'Cash Flow'!$E$39:$FS$39) -> 7659690.6 | P11: =SUMIF('Cash Flow'!$E$13:$FS$13,P$6,'Cash Flow'!$E$39:$FS$39) -> 7892667.4 | Q11: =SUMIF('Cash Flow'!$E$13:$FS$13,Q$6,'Cash Flow'!$E$39:$FS$39) -> 8132730.5 | ... S11: =SUMIF('Cash Flow'!$E$13:$FS$13,S$6,'Cash Flow'!$E$39:$FS$39) -> 8634983.9
F12: Loss to Lease | G12: =J12 -> -84181.874 | J12: =SUMIF('Cash Flow'!E$13:$FS13,J$6,'Cash Flow'!$E$40:$FS$40) -> -84181.874 | K12: =SUMIF('Cash Flow'!F$13:$FS13,K$6,'Cash Flow'!$E$40:$FS$40) -> -120347.5 | L12: =SUMIF('Cash Flow'!G$13:$FS13,L$6,'Cash Flow'!$E$40:$FS$40) -> -66361.2 | M12: =SUMIF('Cash Flow'!H$13:$FS13,M$6,'Cash Flow'!$E$40:$FS$40) -> -40215.158 | N12: =SUMIF('Cash Flow'!I$13:$FS13,N$6,'Cash Flow'!$E$40:$FS$40) -> -48968.645 | O12: =SUMIF('Cash Flow'!J$13:$FS13,O$6,'Cash Flow'!$E$40:$FS$40) -> -57515.926 | P12: =SUMIF('Cash Flow'!K$13:$FS13,P$6,'Cash Flow'!$E$40:$FS$40) -> -58466.943 | Q12: =SUMIF('Cash Flow'!L$13:$FS13,Q$6,'Cash Flow'!$E$40:$FS$40) -> -59155.215 | ... S12: =SUMIF('Cash Flow'!N$13:$FS13,S$6,'Cash Flow'!$E$40:$FS$40) -> -62239.896
B13: GP Equity | C13: =C15-C14 -> 6007066.2 | D13: =C13/$C$15 -> 0.31734614 | F13: Vacancy | G13: =-G11*Detail!F33 -> -330099.16 | H13: =-G13/$G$11 -> 0.05 | J13: =SUMIF('Cash Flow'!E$13:$FS13,J$6,'Cash Flow'!$E$41:$FS$41) -> -331134.16 | K13: =SUMIF('Cash Flow'!F$13:$FS13,K$6,'Cash Flow'!$E$41:$FS$41) -> -338880.48 | L13: =SUMIF('Cash Flow'!G$13:$FS13,L$6,'Cash Flow'!$E$41:$FS$41) -> -348317.06 | M13: =SUMIF('Cash Flow'!H$13:$FS13,M$6,'Cash Flow'!$E$41:$FS$41) -> -358016.41 | N13: =SUMIF('Cash Flow'!I$13:$FS13,N$6,'Cash Flow'!$E$41:$FS$41) -> -367985.86 | O13: =SUMIF('Cash Flow'!J$13:$FS13,O$6,'Cash Flow'!$E$41:$FS$41) -> -378232.92 | P13: =SUMIF('Cash Flow'!K$13:$FS13,P$6,'Cash Flow'!$E$41:$FS$41) -> -388765.32 | Q13: =SUMIF('Cash Flow'!L$13:$FS13,Q$6,'Cash Flow'!$E$41:$FS$41) -> -399591.02 | ... S13: =SUMIF('Cash Flow'!N$13:$FS13,S$6,'Cash Flow'!$E$41:$FS$41) -> -422155.16
B14: LP Equity | C14: 12922000 | D14: =C14/$C$15 -> 0.68265386 | F14: Gross Rental Income | G14: =G11+G13+G12 -> 6187702.1 | H14: =-G14/$G$11 -> -0.937249 | J14: =SUM(J11:J13) -> 6207367.2 | K14: =SUM(K11:K13) -> 6335325.6 | L14: =SUM(L11:L13) -> 6586538.2 | M14: =SUM(M11:M13) -> 6815933.5 | N14: =SUM(N11:N13) -> 7016636.3 | O14: =SUM(O11:O13) -> 7223941.8 | P14: =SUM(P11:P13) -> 7445435.2 | Q14: =SUM(Q11:Q13) -> 7673984.2 | ... S14: =SUM(S11:S13) -> 8150588.8
B15: Total Equity | C15: =Detail!C22 -> 18929066 | D15: =C15/$C$17 -> 0.26649747 | F15: Non-Income Unit Loss | G15: =-G11/$B$4 -> -22923.553 | H15: =-G15/$G$11 -> 0.0034722222 | J15: =SUMIF('Cash Flow'!$E$13:$FS$13,J$6,'Cash Flow'!$E$57:$FS$57) -> -22995.428 | K15: =SUMIF('Cash Flow'!$E$13:$FS$13,K$6,'Cash Flow'!$E$57:$FS$57) -> -23592.2 | L15: =SUMIF('Cash Flow'!$E$13:$FS$13,L$6,'Cash Flow'!$E$57:$FS$57) -> -24309.779 | M15: =SUMIF('Cash Flow'!$E$13:$FS$13,M$6,'Cash Flow'!$E$57:$FS$57) -> -25049.184 | N15: =SUMIF('Cash Flow'!$E$13:$FS$13,N$6,'Cash Flow'!$E$57:$FS$57) -> -25811.079 | O15: =SUMIF('Cash Flow'!$E$13:$FS$13,O$6,'Cash Flow'!$E$57:$FS$57) -> -26596.148 | P15: =SUMIF('Cash Flow'!$E$13:$FS$13,P$6,'Cash Flow'!$E$57:$FS$57) -> -27405.095 | Q15: =SUMIF('Cash Flow'!$E$13:$FS$13,Q$6,'Cash Flow'!$E$57:$FS$57) -> -28238.648 | ... S15: =SUMIF('Cash Flow'!$E$13:$FS$13,S$6,'Cash Flow'!$E$57:$FS$57) -> -29982.583
B16: Debt | C16: =Detail!D22 -> 52100000 | D16: =C16/$C$17 -> 0.73350253 | F16: Collection Loss | G16: =-Detail!F36*G14 -> -61877.021 | H16: =-G16/$G$11 -> 0.00937249 | J16: =SUMIF('Cash Flow'!$E$13:$FS$13,J$6,'Cash Flow'!$E$43:$FS$43) -> -62073.672 | K16: =SUMIF('Cash Flow'!$E$13:$FS$13,K$6,'Cash Flow'!$E$43:$FS$43) -> -63377.623 | L16: =SUMIF('Cash Flow'!$E$13:$FS$13,L$6,'Cash Flow'!$E$43:$FS$43) -> -65931.177 | M16: =SUMIF('Cash Flow'!$E$13:$FS$13,M$6,'Cash Flow'!$E$43:$FS$43) -> -68125.928 | N16: =SUMIF('Cash Flow'!$E$13:$FS$13,N$6,'Cash Flow'!$E$43:$FS$43) -> -70087.994 | O16: =SUMIF('Cash Flow'!$E$13:$FS$13,O$6,'Cash Flow'!$E$43:$FS$43) -> -72179.184 | P16: =SUMIF('Cash Flow'!$E$13:$FS$13,P$6,'Cash Flow'!$E$43:$FS$43) -> -74391.771 | Q16: =SUMIF('Cash Flow'!$E$13:$FS$13,Q$6,'Cash Flow'!$E$43:$FS$43) -> -76662.604 | ... S16: =SUMIF('Cash Flow'!$E$13:$FS$13,S$6,'Cash Flow'!$E$43:$FS$43) -> -81394.662
B17: Total Capitalization | C17: =C15+C16 -> 71029066 | F17: Concession Loss | H17: =-G17/$G$11 -> 0 | J17: =SUMIF('Cash Flow'!$E$13:$FS$13,J$6,'Cash Flow'!$E$44:$FS$44) -> -414003.95 | K17: =SUMIF('Cash Flow'!$E$13:$FS$13,K$6,'Cash Flow'!$E$44:$FS$44) -> -158254.78 | L17: =SUMIF('Cash Flow'!$E$13:$FS$13,L$6,'Cash Flow'!$E$44:$FS$44) -> 0 | M17: =SUMIF('Cash Flow'!$E$13:$FS$13,M$6,'Cash Flow'!$E$44:$FS$44) -> 0 | N17: =SUMIF('Cash Flow'!$E$13:$FS$13,N$6,'Cash Flow'!$E$44:$FS$44) -> 0 | O17: =SUMIF('Cash Flow'!$E$13:$FS$13,O$6,'Cash Flow'!$E$44:$FS$44) -> 0 | P17: =SUMIF('Cash Flow'!$E$13:$FS$13,P$6,'Cash Flow'!$E$44:$FS$44) -> 0 | Q17: =SUMIF('Cash Flow'!$E$13:$FS$13,Q$6,'Cash Flow'!$E$44:$FS$44) -> 0 | ... S17: =SUMIF('Cash Flow'!$E$13:$FS$13,S$6,'Cash Flow'!$E$44:$FS$44) -> 0
F18: Amenity Income | G18: =+P_L!E17+P_L!E19+Detail!M83 -> 810388.8 | H18: =G18/$G$11 -> 0.1227493 | J18: =SUMIF('Cash Flow'!$E$13:$FS$13,J$6,'Cash Flow'!$E$56:$FS$56) -> 797131.61 | K18: =SUMIF('Cash Flow'!$E$13:$FS$13,K$6,'Cash Flow'!$E$56:$FS$56) -> 834026.69 | L18: =SUMIF('Cash Flow'!$E$13:$FS$13,L$6,'Cash Flow'!$E$56:$FS$56) -> 859394.41 | M18: =SUMIF('Cash Flow'!$E$13:$FS$13,M$6,'Cash Flow'!$E$56:$FS$56) -> 885533.71 | N18: =SUMIF('Cash Flow'!$E$13:$FS$13,N$6,'Cash Flow'!$E$56:$FS$56) -> 912468.07 | O18: =SUMIF('Cash Flow'!$E$13:$FS$13,O$6,'Cash Flow'!$E$56:$FS$56) -> 940221.66 | P18: =SUMIF('Cash Flow'!$E$13:$FS$13,P$6,'Cash Flow'!$E$56:$FS$56) -> 968819.4 | Q18: =SUMIF('Cash Flow'!$E$13:$FS$13,Q$6,'Cash Flow'!$E$56:$FS$56) -> 998286.97 | ... S18: =SUMIF('Cash Flow'!$E$13:$FS$13,S$6,'Cash Flow'!$E$56:$FS$56) -> 1059938.2
B20: Residual | F20: Effective Gross Income | G20: =SUM(G14:G19) -> 6913290.3 | H20: =G20/$G$11 -> 1.0471536 | J20: =SUM(J14:J19) -> 6505425.7 | K20: =SUM(K14:K19) -> 6924127.7 | L20: =SUM(L14:L19) -> 7355691.6 | M20: =SUM(M14:M19) -> 7608292.1 | N20: =SUM(N14:N19) -> 7833205.3 | O20: =SUM(O14:O19) -> 8065388.1 | P20: =SUM(P14:P19) -> 8312457.7 | Q20: =SUM(Q14:Q19) -> 8567370 | ... S20: =SUM(S14:S19) -> 9099149.8
B21: Exit Cap | C21: =Detail!M38 -> 0.05
B22: NOI | C22: =Detail!L22 -> 4636539.1 | F22: Variable Expenses | H22: % of EGI
B23: Sales Price | C23: =Detail!L24 -> 92730781 | D23: =C23/$B$4 -> 321981.88 | F23: Payroll | G23: =+P_L!E23 -> 481979 | H23: =G23/$G$20 -> 0.069717743 | J23: =SUMIF('Cash Flow'!$E$13:$FS$13,J$6,'Cash Flow'!$E60:$FS60) -> 482985.36 | K23: =SUMIF('Cash Flow'!$E$13:$FS$13,K$6,'Cash Flow'!$E60:$FS60) -> 491306.31 | L23: =SUMIF('Cash Flow'!$E$13:$FS$13,L$6,'Cash Flow'!$E60:$FS60) -> 501223.01 | M23: =SUMIF('Cash Flow'!$E$13:$FS$13,M$6,'Cash Flow'!$E60:$FS60) -> 511339.87 | N23: =SUMIF('Cash Flow'!$E$13:$FS$13,N$6,'Cash Flow'!$E60:$FS60) -> 521660.94 | O23: =SUMIF('Cash Flow'!$E$13:$FS$13,O$6,'Cash Flow'!$E60:$FS60) -> 532190.33 | P23: =SUMIF('Cash Flow'!$E$13:$FS$13,P$6,'Cash Flow'!$E60:$FS60) -> 542932.25 | Q23: =SUMIF('Cash Flow'!$E$13:$FS$13,Q$6,'Cash Flow'!$E60:$FS60) -> 553890.99 | ... S23: =SUMIF('Cash Flow'!$E$13:$FS$13,S$6,'Cash Flow'!$E60:$FS60) -> 576476.51
B24: Less Closing Costs | C24: =Detail!L26 -> -1159134.8 | D24: =Detail!M39 -> 0.0125 | F24: Administrative | G24: =+P_L!E27 -> 164269 | H24: =G24/$G$20 -> 0.023761334 | J24: =SUMIF('Cash Flow'!$E$13:$FS$13,J$6,'Cash Flow'!$E61:$FS61) -> 164611.99 | K24: =SUMIF('Cash Flow'!$E$13:$FS$13,K$6,'Cash Flow'!$E61:$FS61) -> 167447.95 | L24: =SUMIF('Cash Flow'!$E$13:$FS$13,L$6,'Cash Flow'!$E61:$FS61) -> 170827.78 | M24: =SUMIF('Cash Flow'!$E$13:$FS$13,M$6,'Cash Flow'!$E61:$FS61) -> 174275.83 | N24: =SUMIF('Cash Flow'!$E$13:$FS$13,N$6,'Cash Flow'!$E61:$FS61) -> 177793.47 | O24: =SUMIF('Cash Flow'!$E$13:$FS$13,O$6,'Cash Flow'!$E61:$FS61) -> 181382.12 | P24: =SUMIF('Cash Flow'!$E$13:$FS$13,P$6,'Cash Flow'!$E61:$FS61) -> 185043.2 | Q24: =SUMIF('Cash Flow'!$E$13:$FS$13,Q$6,'Cash Flow'!$E61:$FS61) -> 188778.18 | ... S24: =SUMIF('Cash Flow'!$E$13:$FS$13,S$6,'Cash Flow'!$E61:$FS61) -> 196475.82
B25: Net Proceeds | C25: =Detail!L27 -> 91571646 | F25: Utilities | G25: =+P_L!E24 -> 557957.03 | H25: =G25/$G$20 -> 0.080707884 | J25: =SUMIF('Cash Flow'!$E$13:$FS$13,J$6,'Cash Flow'!$E62:$FS62) -> 559122.03 | K25: =SUMIF('Cash Flow'!$E$13:$FS$13,K$6,'Cash Flow'!$E62:$FS62) -> 568754.68 | L25: =SUMIF('Cash Flow'!$E$13:$FS$13,L$6,'Cash Flow'!$E62:$FS62) -> 580234.62 | M25: =SUMIF('Cash Flow'!$E$13:$FS$13,M$6,'Cash Flow'!$E62:$FS62) -> 591946.28 | N25: =SUMIF('Cash Flow'!$E$13:$FS$13,N$6,'Cash Flow'!$E62:$FS62) -> 603894.34 | O25: =SUMIF('Cash Flow'!$E$13:$FS$13,O$6,'Cash Flow'!$E62:$FS62) -> 616083.56 | P25: =SUMIF('Cash Flow'!$E$13:$FS$13,P$6,'Cash Flow'!$E62:$FS62) -> 628518.81 | Q25: =SUMIF('Cash Flow'!$E$13:$FS$13,Q$6,'Cash Flow'!$E62:$FS62) -> 641205.05 | ... S25: =SUMIF('Cash Flow'!$E$13:$FS$13,S$6,'Cash Flow'!$E62:$FS62) -> 667350.91
F26: Turnover | G26: =+P_L!E28 -> 51840 | H26: =G26/$G$20 -> 0.0074986002 | J26: =SUMIF('Cash Flow'!$E$13:$FS$13,J$6,'Cash Flow'!$E63:$FS63) -> 51948.24 | K26: =SUMIF('Cash Flow'!$E$13:$FS$13,K$6,'Cash Flow'!$E63:$FS63) -> 52843.213 | L26: =SUMIF('Cash Flow'!$E$13:$FS$13,L$6,'Cash Flow'!$E63:$FS63) -> 53909.819 | M26: =SUMIF('Cash Flow'!$E$13:$FS$13,M$6,'Cash Flow'!$E63:$FS63) -> 54997.954 | N26: =SUMIF('Cash Flow'!$E$13:$FS$13,N$6,'Cash Flow'!$E63:$FS63) -> 56108.053 | O26: =SUMIF('Cash Flow'!$E$13:$FS$13,O$6,'Cash Flow'!$E63:$FS63) -> 57240.558 | P26: =SUMIF('Cash Flow'!$E$13:$FS$13,P$6,'Cash Flow'!$E63:$FS63) -> 58395.921 | Q26: =SUMIF('Cash Flow'!$E$13:$FS$13,Q$6,'Cash Flow'!$E63:$FS63) -> 59574.605 | ... S26: =SUMIF('Cash Flow'!$E$13:$FS$13,S$6,'Cash Flow'!$E63:$FS63) -> 62003.827
F27: Repairs and Maintenance | G27: =+P_L!E26 -> 151785 | H27: =G27/$G$20 -> 0.021955537 | J27: =SUMIF('Cash Flow'!$E$13:$FS$13,J$6,'Cash Flow'!$E64:$FS64) -> 152101.92 | K27: =SUMIF('Cash Flow'!$E$13:$FS$13,K$6,'Cash Flow'!$E64:$FS64) -> 154722.36 | L27: =SUMIF('Cash Flow'!$E$13:$FS$13,L$6,'Cash Flow'!$E64:$FS64) -> 157845.33 | M27: =SUMIF('Cash Flow'!$E$13:$FS$13,M$6,'Cash Flow'!$E64:$FS64) -> 161031.34 | N27: =SUMIF('Cash Flow'!$E$13:$FS$13,N$6,'Cash Flow'!$E64:$FS64) -> 164281.65 | O27: =SUMIF('Cash Flow'!$E$13:$FS$13,O$6,'Cash Flow'!$E64:$FS64) -> 167597.57 | P27: =SUMIF('Cash Flow'!$E$13:$FS$13,P$6,'Cash Flow'!$E64:$FS64) -> 170980.42 | Q27: =SUMIF('Cash Flow'!$E$13:$FS$13,Q$6,'Cash Flow'!$E64:$FS64) -> 174431.55 | ... S27: =SUMIF('Cash Flow'!$E$13:$FS$13,S$6,'Cash Flow'!$E64:$FS64) -> 181544.19
F28: Marketing & Advertising | G28: =+P_L!E29 -> 136800 | H28: =G28/$G$20 -> 0.019787973 | J28: =SUMIF('Cash Flow'!$E$13:$FS$13,J$6,'Cash Flow'!$E65:$FS65) -> 137085.63 | K28: =SUMIF('Cash Flow'!$E$13:$FS$13,K$6,'Cash Flow'!$E65:$FS65) -> 139447.37 | L28: =SUMIF('Cash Flow'!$E$13:$FS$13,L$6,'Cash Flow'!$E65:$FS65) -> 142262.02 | M28: =SUMIF('Cash Flow'!$E$13:$FS$13,M$6,'Cash Flow'!$E65:$FS65) -> 145133.49 | N28: =SUMIF('Cash Flow'!$E$13:$FS$13,N$6,'Cash Flow'!$E65:$FS65) -> 148062.92 | O28: =SUMIF('Cash Flow'!$E$13:$FS$13,O$6,'Cash Flow'!$E65:$FS65) -> 151051.47 | P28: =SUMIF('Cash Flow'!$E$13:$FS$13,P$6,'Cash Flow'!$E65:$FS65) -> 154100.35 | Q28: =SUMIF('Cash Flow'!$E$13:$FS$13,Q$6,'Cash Flow'!$E65:$FS65) -> 157210.76 | ... S28: =SUMIF('Cash Flow'!$E$13:$FS$13,S$6,'Cash Flow'!$E65:$FS65) -> 163621.21
F29: Contract Services | G29: =+P_L!E25 -> 30140 | H29: =G29/$G$20 -> 0.0043597185 | J29: =SUMIF('Cash Flow'!$E$13:$FS$13,J$6,'Cash Flow'!$E66:$FS66) -> 30202.931 | K29: =SUMIF('Cash Flow'!$E$13:$FS$13,K$6,'Cash Flow'!$E66:$FS66) -> 30723.272 | L29: =SUMIF('Cash Flow'!$E$13:$FS$13,L$6,'Cash Flow'!$E66:$FS66) -> 31343.402 | M29: =SUMIF('Cash Flow'!$E$13:$FS$13,M$6,'Cash Flow'!$E66:$FS66) -> 31976.048 | N29: =SUMIF('Cash Flow'!$E$13:$FS$13,N$6,'Cash Flow'!$E66:$FS66) -> 32621.464 | O29: =SUMIF('Cash Flow'!$E$13:$FS$13,O$6,'Cash Flow'!$E66:$FS66) -> 33279.907 | P29: =SUMIF('Cash Flow'!$E$13:$FS$13,P$6,'Cash Flow'!$E66:$FS66) -> 33951.641 | Q29: =SUMIF('Cash Flow'!$E$13:$FS$13,Q$6,'Cash Flow'!$E66:$FS66) -> 34636.933 | ... S29: =SUMIF('Cash Flow'!$E$13:$FS$13,S$6,'Cash Flow'!$E66:$FS66) -> 36049.293
F30: Fixed Expenses
F31: Management Fees | G31: =+P_L!E31 -> 190115.48 | H31: =G31/$G$20 -> 0.0275 | J31: =SUMIF('Cash Flow'!$E$13:$FS$13,J$6,'Cash Flow'!$E68:$FS68) -> 178899.21 | K31: =SUMIF('Cash Flow'!$E$13:$FS$13,K$6,'Cash Flow'!$E68:$FS68) -> 190480.52 | L31: =SUMIF('Cash Flow'!$E$13:$FS$13,L$6,'Cash Flow'!$E68:$FS68) -> 202462.46 | M31: =SUMIF('Cash Flow'!$E$13:$FS$13,M$6,'Cash Flow'!$E68:$FS68) -> 209136.16 | N31: =SUMIF('Cash Flow'!$E$13:$FS$13,N$6,'Cash Flow'!$E68:$FS68) -> 215197.63 | O31: =SUMIF('Cash Flow'!$E$13:$FS$13,O$6,'Cash Flow'!$E68:$FS68) -> 221632.53 | P31: =SUMIF('Cash Flow'!$E$13:$FS$13,P$6,'Cash Flow'!$E68:$FS68) -> 228420.49 | Q31: =SUMIF('Cash Flow'!$E$13:$FS$13,Q$6,'Cash Flow'!$E68:$FS68) -> 235390.27 | ... S31: =SUMIF('Cash Flow'!$E$13:$FS$13,S$6,'Cash Flow'!$E68:$FS68) -> 249920.75
F32: HOA | G32: =+P_L!E32 -> 14652 | H32: =G32/$G$20 -> 0.002119396 | J32: =SUMIF('Cash Flow'!$E$13:$FS$13,J$6,'Cash Flow'!$E70:$FS70) -> 14682.593 | K32: =SUMIF('Cash Flow'!$E$13:$FS$13,K$6,'Cash Flow'!$E70:$FS70) -> 14935.547 | L32: =SUMIF('Cash Flow'!$E$13:$FS$13,L$6,'Cash Flow'!$E70:$FS70) -> 15237.011 | M32: =SUMIF('Cash Flow'!$E$13:$FS$13,M$6,'Cash Flow'!$E70:$FS70) -> 15544.561 | N32: =SUMIF('Cash Flow'!$E$13:$FS$13,N$6,'Cash Flow'!$E70:$FS70) -> 15858.318 | O32: =SUMIF('Cash Flow'!$E$13:$FS$13,O$6,'Cash Flow'!$E70:$FS70) -> 16178.408 | P32: =SUMIF('Cash Flow'!$E$13:$FS$13,P$6,'Cash Flow'!$E70:$FS70) -> 16504.958 | Q32: =SUMIF('Cash Flow'!$E$13:$FS$13,Q$6,'Cash Flow'!$E70:$FS70) -> 16838.1 | ... S32: =SUMIF('Cash Flow'!$E$13:$FS$13,S$6,'Cash Flow'!$E70:$FS70) -> 17524.693
F33: RE Taxes | G33: =+P_L!E34 -> 723196.89 | H33: =G33/$G$20 -> 0.10460965 | J33: =SUMIF('Cash Flow'!$E$13:$FS$13,J$6,'Cash Flow'!$E69:$FS69) -> 724706.9 | K33: =SUMIF('Cash Flow'!$E$13:$FS$13,K$6,'Cash Flow'!$E69:$FS69) -> 737192.27 | L33: =SUMIF('Cash Flow'!$E$13:$FS$13,L$6,'Cash Flow'!$E69:$FS69) -> 752072.02 | M33: =SUMIF('Cash Flow'!$E$13:$FS$13,M$6,'Cash Flow'!$E69:$FS69) -> 767252.11 | N33: =SUMIF('Cash Flow'!$E$13:$FS$13,N$6,'Cash Flow'!$E69:$FS69) -> 782738.6 | O33: =SUMIF('Cash Flow'!$E$13:$FS$13,O$6,'Cash Flow'!$E69:$FS69) -> 798537.68 | P33: =SUMIF('Cash Flow'!$E$13:$FS$13,P$6,'Cash Flow'!$E69:$FS69) -> 814655.65 | Q33: =SUMIF('Cash Flow'!$E$13:$FS$13,Q$6,'Cash Flow'!$E69:$FS69) -> 831098.95 | ... S33: =SUMIF('Cash Flow'!$E$13:$FS$13,S$6,'Cash Flow'!$E69:$FS69) -> 864987.94
F34: Insurance - Property | G34: =+P_L!E33 -> 302400 | H34: =G34/$G$20 -> 0.043741834 | J34: =SUMIF('Cash Flow'!$E$13:$FS$13,J$6,'Cash Flow'!$E71:$FS71) -> 303031.4 | K34: =SUMIF('Cash Flow'!$E$13:$FS$13,K$6,'Cash Flow'!$E71:$FS71) -> 308252.08 | L34: =SUMIF('Cash Flow'!$E$13:$FS$13,L$6,'Cash Flow'!$E71:$FS71) -> 314473.95 | M34: =SUMIF('Cash Flow'!$E$13:$FS$13,M$6,'Cash Flow'!$E71:$FS71) -> 320821.4 | N34: =SUMIF('Cash Flow'!$E$13:$FS$13,N$6,'Cash Flow'!$E71:$FS71) -> 327296.97 | O34: =SUMIF('Cash Flow'!$E$13:$FS$13,O$6,'Cash Flow'!$E71:$FS71) -> 333903.25 | P34: =SUMIF('Cash Flow'!$E$13:$FS$13,P$6,'Cash Flow'!$E71:$FS71) -> 340642.87 | Q34: =SUMIF('Cash Flow'!$E$13:$FS$13,Q$6,'Cash Flow'!$E71:$FS71) -> 347518.53 | ... S34: =SUMIF('Cash Flow'!$E$13:$FS$13,S$6,'Cash Flow'!$E71:$FS71) -> 361688.99
F35: Capital Reserves | G35: =+P_L!E35 -> 57600 | H35: =G35/$G$20 -> 0.008331778 | J35: =SUMIF('Cash Flow'!$E$13:$FS$13,J$6,'Cash Flow'!$E72:$FS72) -> 57600 | K35: =SUMIF('Cash Flow'!$E$13:$FS$13,K$6,'Cash Flow'!$E72:$FS72) -> 57600 | L35: =SUMIF('Cash Flow'!$E$13:$FS$13,L$6,'Cash Flow'!$E72:$FS72) -> 57600 | M35: =SUMIF('Cash Flow'!$E$13:$FS$13,M$6,'Cash Flow'!$E72:$FS72) -> 57600 | N35: =SUMIF('Cash Flow'!$E$13:$FS$13,N$6,'Cash Flow'!$E72:$FS72) -> 57600 | O35: =SUMIF('Cash Flow'!$E$13:$FS$13,O$6,'Cash Flow'!$E72:$FS72) -> 57600 | P35: =SUMIF('Cash Flow'!$E$13:$FS$13,P$6,'Cash Flow'!$E72:$FS72) -> 57600 | Q35: =SUMIF('Cash Flow'!$E$13:$FS$13,Q$6,'Cash Flow'!$E72:$FS72) -> 57600 | ... S35: =SUMIF('Cash Flow'!$E$13:$FS$13,S$6,'Cash Flow'!$E72:$FS72) -> 57600
F36: Total Operating Expenses | G36: =SUM(G23:G35) -> 2862734.4 | H36: =G36/$G$20 -> 0.41409145 | J36: =SUM(J23:J35) -> 2856978.2 | K36: =SUM(K23:K35) -> 2913705.6 | L36: =SUM(L23:L35) -> 2979491.4 | M36: =SUM(M23:M35) -> 3041055.1 | N36: =SUM(N23:N35) -> 3103114.4 | O36: =SUM(O23:O35) -> 3166677.4 | P36: =SUM(P23:P35) -> 3231746.6 | Q36: =SUM(Q23:Q35) -> 3298173.9 | ... S36: =SUM(S23:S35) -> 3435244.1
F38: Net Operating Income | G38: =G20-G36 -> 4050555.9 | J38: =J20-J36 -> 3648447.5 | K38: =K20-K36 -> 4010422.1 | L38: =L20-L36 -> 4376200.2 | M38: =M20-M36 -> 4567237.1 | N38: =N20-N36 -> 4730091 | O38: =O20-O36 -> 4898710.7 | P38: =P20-P36 -> 5080711.2 | Q38: =Q20-Q36 -> 5269196 | ... S38: =S20-S36 -> 5663905.7
F39: NOI Growth | K39: =K38/J38-1 -> 0.099213315 | L39: =L38/K38-1 -> 0.091206877 | M39: =M38/L38-1 -> 0.043653602 | N39: =N38/M38-1 -> 0.035656981 | O39: =O38/N38-1 -> 0.03564831 | P39: =P38/O38-1 -> 0.037152721 | Q39: =Q38/P38-1 -> 0.037098132 | R39: =R38/Q38-1 -> 0.036882441 | S39: =S38/R38-1 -> 0.036673828
F40: Debt Service | J40: =-(SUMIF('Cash Flow'!$E$13:$FS13,J$6,'Cash Flow'!$E81:$FS81)+SUMIF('Cash Flow'!$E$13:$FS13,J$6,'Cash Flow'!$E82:$FS82)) -> -3037357.6 | K40: =-(SUMIF('Cash Flow'!$E$13:$FS13,K$6,'Cash Flow'!$E81:$FS81)+SUMIF('Cash Flow'!$E$13:$FS13,K$6,'Cash Flow'!$E82:$FS82)) -> -3045679.2 | L40: =-(SUMIF('Cash Flow'!$E$13:$FS13,L$6,'Cash Flow'!$E81:$FS81)+SUMIF('Cash Flow'!$E$13:$FS13,L$6,'Cash Flow'!$E82:$FS82)) -> -3037357.6 | M40: =-(SUMIF('Cash Flow'!$E$13:$FS13,M$6,'Cash Flow'!$E81:$FS81)+SUMIF('Cash Flow'!$E$13:$FS13,M$6,'Cash Flow'!$E82:$FS82)) -> -3037357.6 | N40: =-(SUMIF('Cash Flow'!$E$13:$FS13,N$6,'Cash Flow'!$E81:$FS81)+SUMIF('Cash Flow'!$E$13:$FS13,N$6,'Cash Flow'!$E82:$FS82)) -> 0 | O40: =-(SUMIF('Cash Flow'!$E$13:$FS13,O$6,'Cash Flow'!$E81:$FS81)+SUMIF('Cash Flow'!$E$13:$FS13,O$6,'Cash Flow'!$E82:$FS82)) -> 0 | P40: =-(SUMIF('Cash Flow'!$E$13:$FS13,P$6,'Cash Flow'!$E81:$FS81)+SUMIF('Cash Flow'!$E$13:$FS13,P$6,'Cash Flow'!$E82:$FS82)) -> 0 | Q40: =-(SUMIF('Cash Flow'!$E$13:$FS13,Q$6,'Cash Flow'!$E81:$FS81)+SUMIF('Cash Flow'!$E$13:$FS13,Q$6,'Cash Flow'!$E82:$FS82)) -> 0 | ... S40: =-(SUMIF('Cash Flow'!$E$13:$FS13,S$6,'Cash Flow'!$E81:$FS81)+SUMIF('Cash Flow'!$E$13:$FS13,S$6,'Cash Flow'!$E82:$FS82)) -> 0
F41: DSCR | J41: =-IFERROR(J38/J40,0) -> 1.2011913 | K41: =-IFERROR(K38/K40,0) -> 1.3167579 | L41: =-IFERROR(L38/L40,0) -> 1.4407919 | M41: =-IFERROR(M38/M40,0) -> 1.5036876 | N41: =-IFERROR(N38/N40,0) -> 0 | O41: =-IFERROR(O38/O40,0) -> 0 | P41: =-IFERROR(P38/P40,0) -> 0 | Q41: =-IFERROR(Q38/Q40,0) -> 0 | ... S41: =-IFERROR(S38/S40,0) -> 0
F43: Cash Flow After Debt Service | J43: =SUMIF('Cash Flow'!$E$13:$FS13,J$6,'Cash Flow'!$E84:$FS84) -> 611089.9 | K43: =SUMIF('Cash Flow'!$E$13:$FS13,K$6,'Cash Flow'!$E84:$FS84) -> 967179.66 | L43: =SUMIF('Cash Flow'!$E$13:$FS13,L$6,'Cash Flow'!$E84:$FS84) -> 1345422.1 | M43: =SUMIF('Cash Flow'!$E$13:$FS13,M$6,'Cash Flow'!$E84:$FS84) -> 1526538.7 | N43: =SUMIF('Cash Flow'!$E$13:$FS13,N$6,'Cash Flow'!$E84:$FS84) -> 0 | O43: =SUMIF('Cash Flow'!$E$13:$FS13,O$6,'Cash Flow'!$E84:$FS84) -> 0 | P43: =SUMIF('Cash Flow'!$E$13:$FS13,P$6,'Cash Flow'!$E84:$FS84) -> 0 | Q43: =SUMIF('Cash Flow'!$E$13:$FS13,Q$6,'Cash Flow'!$E84:$FS84) -> 0 | ... S43: =SUMIF('Cash Flow'!$E$13:$FS13,S$6,'Cash Flow'!$E84:$FS84) -> 0
F45: Equity Invested | J45: =C15 -> 18929066 | K45: =J45 -> 18929066 | L45: =K45 -> 18929066 | M45: =L45 -> 18929066 | N45: =M45 -> 18929066 | O45: 0 | P45: 0 | Q45: =P45 -> 0 | R45: =Q45 -> 0 | S45: =R45 -> 0
...

Sheet P_L
B2: =+Detail!C6 -> Sentosa Epperson | P2: =+Detail!C7 -> Wesley Chapel, FL
B5: UNTRENDED STABILIZED OPERATING INCOME STATEMENT
E6: 0
E7: Annual | I7: Month
E8: Total | F8: Per Unit | G8: Per NRSF | I8: Total | J8: Per Unit | K8: Per NRSF
B9: MULTIFAMILY | D9: % of GPR
B10: Gross Potential Rent | E10: =+Detail!M67 -> 6601983.1 | F10: =+E10/Detail!$C$8 -> 22923.553 | G10: =+E10/Detail!$C$10 -> 22.455725 | I10: =E10/12 -> 550165.26 | J10: =+I10/Detail!$C$8 -> 1910.296 | K10: =+I10/Detail!$C$10 -> 1.8713104
B11: Loss to Lease | D11: =IFERROR(ABS(E11/E$10),0) -> 0.012750998 | E11: =Summary!G12 -> -84181.874 | F11: =+E11/Detail!$C$8 -> -292.29817 | G11: =+E11/Detail!$C$10 -> -0.2863329 | I11: =E11/12 -> -7015.1561 | J11: =+I11/Detail!$C$8 -> -24.358181 | K11: =+I11/Detail!$C$10 -> -0.023861075
B12: Vacancy | D12: =IFERROR(ABS(E12/E$10),0) -> 0.05 | E12: =-E10*Detail!F33 -> -330099.16 | F12: =+E12/Detail!$C$8 -> -1146.1776 | G12: =+E12/Detail!$C$10 -> -1.1227862 | I12: =E12/12 -> -27508.263 | J12: =+I12/Detail!$C$8 -> -95.514802 | K12: =+I12/Detail!$C$10 -> -0.09356552
B13: Gross Rental Income | D13: =IFERROR(ABS(E13/E$10),0) -> 0.937249 | E13: =SUM(E10:E12) -> 6187702.1 | F13: =SUM(F10:F12) -> 21485.077 | G13: =SUM(G10:G12) -> 21.046606 | I13: =E13/12 -> 515641.84 | J13: =SUM(J10:J12) -> 1790.4231 | K13: =SUM(K10:K12) -> 1.7538838
B14: Non-Income Unit Loss | D14: =IFERROR(ABS(E14/E$10),0) -> 0.0034722222 | E14: =-E10/Detail!C8 -> -22923.553 | F14: =+E14/Detail!$C$8 -> -79.595668 | G14: =+E14/Detail!$C$10 -> -0.077971267 | I14: =E14/12 -> -1910.296 | J14: =+I14/Detail!$C$8 -> -6.6329724 | K14: =+I14/Detail!$C$10 -> -0.0064976056
B15: Collection Loss | D15: =IFERROR(ABS(E15/E$10),0) -> 0.00937249 | E15: =-E13*Detail!F36 -> -61877.021 | F15: =+E15/Detail!$C$8 -> -214.85077 | G15: =+E15/Detail!$C$10 -> -0.21046606 | I15: =E15/12 -> -5156.4184 | J15: =+I15/Detail!$C$8 -> -17.904231 | K15: =+I15/Detail!$C$10 -> -0.017538838
B16: Concession Loss | D16: =IFERROR(ABS(E16/E$10),0) -> 0 | E16: 0 | F16: =+E16/Detail!$C$8 -> 0 | G16: =+E16/Detail!$C$10 -> 0 | I16: =E16/12 -> 0 | J16: =+I16/Detail!$C$8 -> 0 | K16: =+I16/Detail!$C$10 -> 0
B17: Amenity Income | D17: =IFERROR(ABS(E17/E$10),0) -> 0.014788284 | E17: =+Detail!M75 -> 97632 | F17: =+E17/Detail!$C$8 -> 339 | G17: =+E17/Detail!$C$10 -> 0.33208163 | I17: =E17/12 -> 8136 | J17: =+I17/Detail!$C$8 -> 28.25 | K17: =+I17/Detail!$C$10 -> 0.027673469
B18: Monthly Recurring Income | D18: =IFERROR(ABS(E18/E$10),0) -> 0.10429666 | E18: =+Detail!M83 -> 688564.8 | F18: =+E18/Detail!$C$8 -> 2390.85 | G18: =+E18/Detail!$C$10 -> 2.3420571 | I18: =E18/12 -> 57380.4 | J18: =+I18/Detail!$C$8 -> 199.2375 | K18: =+I18/Detail!$C$10 -> 0.19517143
B19: Other Income | D19: =IFERROR(ABS(E19/E$10),0) -> 0.0036643535 | E19: =+Detail!M85 -> 24192 | F19: =+E19/Detail!$C$8 -> 84 | G19: =+E19/Detail!$C$10 -> 0.082285714 | I19: =E19/12 -> 2016 | J19: =+I19/Detail!$C$8 -> 7 | K19: =+I19/Detail!$C$10 -> 0.0068571429
B20: Effective Gross Income | D20: =IFERROR(ABS(E20/E$10),0) -> 1.0471536 | E20: =SUM(E13:E19) -> 6913290.3 | F20: =SUM(F13:F19) -> 24004.48 | G20: =SUM(G13:G19) -> 23.514593 | I20: =SUM(I13:I19) -> 576107.53 | J20: =SUM(J13:J19) -> 2000.3734 | K20: =SUM(K13:K19) -> 1.9595494
D21: % of EGI
B22: Variable Expenses
B23: Payroll | D23: =IFERROR(ABS(E23/E$20),0) -> 0.069717743 | E23: =+Detail!M98 -> 481979 | F23: =+E23/Detail!$C$8 -> 1673.5382 | G23: =+E23/Detail!$C$10 -> 1.6393844 | I23: =E23/12 -> 40164.917 | J23: =+I23/Detail!$C$8 -> 139.46152 | K23: =+I23/Detail!$C$10 -> 0.13661536
B24: Utilities | D24: =IFERROR(ABS(E24/E$20),0) -> 0.080707884 | E24: =+Detail!M99 -> 557957.03 | F24: =+E24/Detail!$C$8 -> 1937.3508 | G24: =+E24/Detail!$C$10 -> 1.897813 | I24: =E24/12 -> 46496.419 | J24: =+I24/Detail!$C$8 -> 161.4459 | K24: =+I24/Detail!$C$10 -> 0.15815109
B25: Contract Services | D25: =IFERROR(ABS(E25/E$20),0) -> 0.0043597185 | E25: =+Detail!M100 -> 30140 | F25: =+E25/Detail!$C$8 -> 104.65278 | G25: =+E25/Detail!$C$10 -> 0.10251701 | I25: =E25/12 -> 2511.6667 | J25: =+I25/Detail!$C$8 -> 8.7210648 | K25: =+I25/Detail!$C$10 -> 0.0085430839
B26: Maintenance | D26: =IFERROR(ABS(E26/E$20),0) -> 0.021955537 | E26: =+Detail!M101 -> 151785 | F26: =+E26/Detail!$C$8 -> 527.03125 | G26: =+E26/Detail!$C$10 -> 0.51627551 | I26: =E26/12 -> 12648.75 | J26: =+I26/Detail!$C$8 -> 43.919271 | K26: =+I26/Detail!$C$10 -> 0.043022959
B27: Administrative | D27: =IFERROR(ABS(E27/E$20),0) -> 0.023761334 | E27: =+Detail!M102 -> 164269 | F27: =+E27/Detail!$C$8 -> 570.37847 | G27: =+E27/Detail!$C$10 -> 0.5587381 | I27: =E27/12 -> 13689.083 | J27: =+I27/Detail!$C$8 -> 47.531539 | K27: =+I27/Detail!$C$10 -> 0.046561508
B28: Turnover | D28: =IFERROR(ABS(E28/E$20),0) -> 0.0074986002 | E28: =+Detail!M103 -> 51840 | F28: =+E28/Detail!$C$8 -> 180 | G28: =+E28/Detail!$C$10 -> 0.17632653 | I28: =E28/12 -> 4320 | J28: =+I28/Detail!$C$8 -> 15 | K28: =+I28/Detail!$C$10 -> 0.014693878
B29: Marketing | D29: =IFERROR(ABS(E29/E$20),0) -> 0.019787973 | E29: =+Detail!M104 -> 136800 | F29: =+E29/Detail!$C$8 -> 475 | G29: =+E29/Detail!$C$10 -> 0.46530612 | I29: =E29/12 -> 11400 | J29: =+I29/Detail!$C$8 -> 39.583333 | K29: =+I29/Detail!$C$10 -> 0.03877551
B30: Fixed Expenses
B31: Management Expense | D31: =IFERROR(ABS(E31/E$20),0) -> 0.0275 | E31: =+Detail!M107 -> 190115.48 | F31: =+E31/Detail!$C$8 -> 660.12321 | G31: =+E31/Detail!$C$10 -> 0.64665131 | I31: =E31/12 -> 15842.957 | J31: =+I31/Detail!$C$8 -> 55.010267 | K31: =+I31/Detail!$C$10 -> 0.053887609
B32: HOA | D32: =IFERROR(ABS(E32/E$20),0) -> 0.002119396 | E32: =+Detail!M108 -> 14652 | F32: =+E32/Detail!$C$8 -> 50.875 | G32: =+E32/Detail!$C$10 -> 0.049836735 | I32: =E32/12 -> 1221 | J32: =+I32/Detail!$C$8 -> 4.2395833 | K32: =+I32/Detail!$C$10 -> 0.0041530612
B33: Insurance | D33: =IFERROR(ABS(E33/E$20),0) -> 0.043741834 | E33: =+Detail!M109 -> 302400 | F33: =+E33/Detail!$C$8 -> 1050 | G33: =+E33/Detail!$C$10 -> 1.0285714 | I33: =E33/12 -> 25200 | J33: =+I33/Detail!$C$8 -> 87.5 | K33: =+I33/Detail!$C$10 -> 0.085714286
B34: Taxes | D34: =IFERROR(ABS(E34/E$20),0) -> 0.10460965 | E34: =+Detail!M110 -> 723196.89 | F34: =+E34/Detail!$C$8 -> 2511.1003 | G34: =+E34/Detail!$C$10 -> 2.4598534 | I34: =E34/12 -> 60266.408 | J34: =+I34/Detail!$C$8 -> 209.25836 | K34: =+I34/Detail!$C$10 -> 0.20498778
B35: Capital Reserves | D35: =IFERROR(ABS(E35/E$20),0) -> 0.008331778 | E35: =+Detail!M112 -> 57600 | F35: =+E35/Detail!$C$8 -> 200 | G35: =+E35/Detail!$C$10 -> 0.19591837 | I35: =E35/12 -> 4800 | J35: =+I35/Detail!$C$8 -> 16.666667 | K35: =+I35/Detail!$C$10 -> 0.016326531
B36: Total Operating Expenses | D36: =IFERROR(ABS(E36/E$20),0) -> 0.41409145 | E36: =SUM(E23:E35) -> 2862734.4 | F36: =SUM(F23:F35) -> 9940.05 | G36: =SUM(G23:G35) -> 9.7371919 | I36: =SUM(I23:I35) -> 238561.2 | J36: =SUM(J23:J35) -> 828.3375 | K36: =SUM(K23:K35) -> 0.81143265
B38: Multifamily NOI | D38: =IFERROR(ABS(E38/E$20),0) -> 0.58590855 | E38: =E20-E36 -> 4050555.9 | F38: =F20-F36 -> 14064.43 | G38: =G20-G36 -> 13.777401 | I38: =I20-I36 -> 337546.33 | J38: =J20-J36 -> 1172.0359 | K38: =K20-K36 -> 1.1481168
E40: =+E38-Summary!G38 -> 0

Sheet Detail
B2: =+Detail!C6 -> Sentosa Epperson | M2: =+P_L!P2 -> Wesley Chapel, FL
B5: PROGRAM | G5: TIMING | H5: Month # | I5: Date | K5: RETURN METRICS
B6: Project | C6: Sentosa Epperson | G6: Lease-up | H6: 0 | I6: 46174 | K6: IRR | M6: ='Cash Flow'!C120 -> 0.25455542
B7: City, State | C7: Wesley Chapel, FL | D7: Parking (Stalls) | G7: Acquisition | H7: 0 | I7: =+EOMONTH($I$6,H7) -> 46203 | K7: Multiple | M7: ='Cash Flow'!C121 -> 2.3245639
B8: Units | C8: =+Detail!D67 -> 288 | D8: Apartments | E8: 434 | G8: Refinance | H8: 47 | I8: =+EOMONTH($I$6,H8) -> 47634 | K8: Profit | M8: ='Cash Flow'!C122 -> 24992810
B9: Average NRSF/Unit | C9: =+Detail!F67 -> 1020.8333 | D9: Commercial | E9: 0 | G9: Disposition | H9: 47 | I9: =+EOMONTH($I$6,H9) -> 47634 | K9: Equity Investment | M9: =-C22 -> -18929066
B10: NRSF (Apts) | C10: =+Detail!G67 -> 294000 | D10: Total Stalls | E10: =SUM(E8:E9) -> 434
B11: NRSF (Coml) | C11: 0 | D11: Resi Ratio | E11: =E8/C8 -> 1.5069444
B12: NRSF (Total) | C12: =SUM(C10:C11) -> 294000 | D12: Comm. Ratio | E12: 0/1,000
B13: GSF (Total) | C13: =C12*1.15 -> 338100 | D13: Land (Gross Acres) | E13: 12
B14: Efficiency | C14: =C12/C13 -> 0.86956522 | D14: Land GSF | E14: =E13*43560 -> 522720
B15: Property Type | C15: Garden | D15: Land (Net Acres) | E15: 24
B16: Buildings | C16: 8 | D16: Land NSF | E16: =E15*43560 -> 1045440
B17: Stories | C17: 3 & 4 Stories | D17: Density (Units) | E17: =C8/E15 -> 12
B18: Constr. Type | C18: Type V | D18: FAR | E18: =C13/(E15*43560) -> 0.3234045
B20: CAPITALIZATION | C20: Equity | D20: Acquisition Loan | E20: Refinance | G20: ACQUISITION SUMMARY | K20: SALE SUMMARY
E21: NO | H21: Total | I21: $ / Unit | L21: Total | M21: $ / Unit
B22: Amount | C22: =$H$28*C23 -> 18929066 | D22: 52100000 | E22: =IF(E21="YES", -PV(E26/12, E27*12, (INDEX('Cash Flow'!$E$17:$FS$76, ROWS('Cash Flow'!$E$17:$E$76), MATCH(E25,'Cash Flow'!$E$17:$FS$17, 0))*12)/12/E29), 0) -> 0 | G22: Stabilized NOI | H22: =P_L!E38 -> 4050555.9 | I22: =H22/$D$67 -> 14064.43 | K22: SALE NOI | L22: =SUMIF('Cash Flow'!$E$17:$FS$17,$H$9,'Cash Flow'!$E$76:$FS$76)*12 -> 4636539.1 | M22: =L22/$D$67 -> 16099.094
B23: % of Total Cost | C23: =1-D23 -> 0.26649747 | D23: =D22/H28 -> 0.73350253 | K23: Cap Rate | L23: =M38 -> 0.05
B24: % of Equity | G24: Cap Rate | H24: =H22/H25 -> 0.057026737 | K24: Sale Price | L24: =L22/L23 -> 92730781 | M24: =L24/$D$67 -> 321981.88
B25: First Draw | D25: =+H7 -> 0 | E25: =H8 -> 47 | G25: Purchase Price | H25: 71029066 | I25: =H25/$D$67 -> 246628.7
B26: Interest Rate | D26: =3%+2.75% -> 0.0575 | E26: 0.05 | K26: Closing Costs | L26: =-L24*M39 -> -1159134.8 | M26: =L26/$D$67 -> -4024.7735
B27: Amortization (Yrs) | D27: 30 | E27: 30 | G27: Closing Costs | H27: =H25*L39 -> 0 | I27: =H27/$D$67 -> 0 | K27: Net Sale Proceeds | L27: =L24+L26 -> 91571646 | M27: =L27/$D$67 -> 317957.11
B28: Interest Only (Mts) | D28: 36 | E28: 12 | G28: Total Costs | H28: =H27+H25 -> 71029066 | I28: =H28/$D$67 -> 246628.7
B29: DSCR | D29: 1.1 | E29: 1.25
B30: 0.015 | E30: =IFERROR(-E22*B30, 0) -> 0
B32: GENERAL OPERATIONS
B33: General/Static Vacancy | F33: 0.05 | G33: Per Year | I33: Total Units | M33: =D67 -> 288
B34: Stabilized Occupancy | F34: =100%-$F$33 -> 0.95 | G34: Per Year | I34: Non-Income Units | M34: 1
B35: Turnover Rate | F35: 0.5 | G35: Per Year | I35: Rentable Units | M35: =M33-M34 -> 287
B36: Collection Loss | F36: 0.01 | G36: Per Year
B37: See Growth Rate Assumptions at bottom of tab for trending operation line items | I37: Purchase Price Cap Rate | M37: =H24 -> 0.057026737
I38: Residual Cap Rate | M38: 0.05
B39: Growth Rates commence at the start of building operations | I39: Closing Costs (Acq / Exit) | L39: 0 | M39: 0.0125
B41: MULTIFAMILY INCOME
B43: Unit Income
B45: Unit Type | D45: Quantity | G45: Total | H45: Base Rent / | I45: Base Rent / | J45: Base Rent / | K45: Base Rent | L45: Total Base
B46: BR / BA | C46: Description | D46: of Units | E46: Unit Mix | F46: NRSF / Unit | G46: NRSF | H46: Unit / Month | I46: / NRSF / Month | J46: Unit / Year | K46: / NRSF / Year | L46: Rent / Month | M46: Rent / Year
B47: 1 Bedroom/1 Bath | C47: A2 | D47: 66 | E47: =+D47/$D$67 -> 0.22916667 | F47: 813 | G47: =+F47*D47 -> 53658 | H47: 1706.88 | I47: =+H47/F47 -> 2.0994834 | J47: =+H47*12 -> 20482.56 | K47: =+M47/G47 -> 25.193801 | L47: =+H47*D47 -> 112654.08 | M47: =+J47*D47 -> 1351849
B48: 1 Bedroom/1 Bath | C48: A2S | D48: 66 | E48: =+D48/$D$67 -> 0.22916667 | F48: 886 | G48: =+F48*D48 -> 58476 | H48: 1679.67 | I48: =+H48/F48 -> 1.8957901 | J48: =+H48*12 -> 20156.04 | K48: =+M48/G48 -> 22.749481 | L48: =+H48*D48 -> 110858.22 | M48: =+J48*D48 -> 1330298.6
...

Sheet Cash Flow
E1: 3 | F1: 10 | G1: 10 | H1: 15 | I1: 15 | J1: 25 | K1: 25 | L1: 25 | M1: 25 | N1: 33 | O1: 27 | P1: 27 | Q1: 15 | R1: 8 | S1: 5 | T1: 5 | U1: 15 | V1: 20 | W1: 20 | X1: 18
B2: MONTHLY | FT2: =Detail!C6 -> Sentosa Epperson
B4: Monthly Operating Cash Flow
B5: Stabilization Date: | C5: =C11 -> 46203 | D5: =EOMONTH(E5,-1) -> 46173 | E5: =EOMONTH(Detail!I6,0) -> 46203 | F5: =EOMONTH(E5,1) -> 46234 | G5: =EOMONTH(F5,1) -> 46265 | H5: =EOMONTH(G5,1) -> 46295 | I5: =EOMONTH(H5,1) -> 46326 | J5: =EOMONTH(I5,1) -> 46356 | K5: =EOMONTH(J5,1) -> 46387 | L5: =EOMONTH(K5,1) -> 46418 | M5: =EOMONTH(L5,1) -> 46446 | ... FS5: =EOMONTH(FR5,1) -> 51379 | FT5: =YEAR(E5) -> 2026 | FU5: =FT5+1 -> 2027 | FV5: =FU5+1 -> 2028 | FW5: =FV5+1 -> 2029 | FX5: =FW5+1 -> 2030
B6: Mapping | E6: =E7&"-"&E8 -> 6-2026 | F6: =F7&"-"&F8 -> 7-2026 | G6: =G7&"-"&G8 -> 8-2026 | H6: =H7&"-"&H8 -> 9-2026 | I6: =I7&"-"&I8 -> 10-2026 | J6: =J7&"-"&J8 -> 11-2026 | K6: =K7&"-"&K8 -> 12-2026 | L6: =L7&"-"&L8 -> 1-2027 | ... FS6: =FS7&"-"&FS8 -> 8-2040
B7: Mapping | E7: =MONTH(E5) -> 6 | F7: =MONTH(F5) -> 7 | G7: =MONTH(G5) -> 8 | H7: =MONTH(H5) -> 9 | I7: =MONTH(I5) -> 10 | J7: =MONTH(J5) -> 11 | K7: =MONTH(K5) -> 12 | L7: =MONTH(L5) -> 1 | ... FS7: =MONTH(FS5) -> 8
B8: Mapping | E8: =YEAR(E5) -> 2026 | F8: =YEAR(F5) -> 2026 | G8: =YEAR(G5) -> 2026 | H8: =YEAR(H5) -> 2026 | I8: =YEAR(I5) -> 2026 | J8: =YEAR(J5) -> 2026 | K8: =YEAR(K5) -> 2026 | L8: =YEAR(L5) -> 2027 | ... FS8: =YEAR(FS5) -> 2040
B9: Mapping | E9: =ROUNDUP(MONTH(E5)/3,0) -> 2 | F9: =ROUNDUP(MONTH(F5)/3,0) -> 3 | G9: =ROUNDUP(MONTH(G5)/3,0) -> 3 | H9: =ROUNDUP(MONTH(H5)/3,0) -> 3 | I9: =ROUNDUP(MONTH(I5)/3,0) -> 4 | J9: =ROUNDUP(MONTH(J5)/3,0) -> 4 | K9: =ROUNDUP(MONTH(K5)/3,0) -> 4 | L9: =ROUNDUP(MONTH(L5)/3,0) -> 1 | ... FS9: =ROUNDUP(MONTH(FS5)/3,0) -> 3
B10: Mapping | C10: {=INDEX(E10:FS10,MATCH(TRUE,E10:FS10<>"",0))} -> 0 | E10: =IF(E31>94%,E17,"") -> 0 | F10: =IF(F31>94%,F17,"") -> 1 | G10: =IF(G31>94%,G17,"") -> 2 | H10: =IF(H31>94%,H17,"") -> 3 | I10: =IF(I31>94%,I17,"") -> 4 | J10: =IF(J31>94%,J17,"") -> 5 | K10: =IF(K31>94%,K17,"") -> 6 | L10: =IF(L31>94%,L17,"") -> 7 | ... FS10: =IF(FS31>94%,FS17,"") -> 170
B11: Mapping | C11: {=INDEX(E11:FS11,MATCH(TRUE,E11:FS11<>"",0))} -> 46203 | E11: =IF(E31>94%,E5,"") -> 46203 | F11: =IF(F31>94%,F5,"") -> 46234 | G11: =IF(G31>94%,G5,"") -> 46265 | H11: =IF(H31>94%,H5,"") -> 46295 | I11: =IF(I31>94%,I5,"") -> 46326 | J11: =IF(J31>94%,J5,"") -> 46356 | K11: =IF(K31>94%,K5,"") -> 46387 | L11: =IF(L31>94%,L5,"") -> 46418 | ... FS11: =IF(FS31>94%,FS5,"") -> 51379
B12: Year | E12: =+IF(E17>=Detail!$H$7,'Cash Flow'!D12+1,0) -> 1 | F12: =+IF(F17>=Detail!$H$7,'Cash Flow'!E12+1,0) -> 2 | G12: =+IF(G17>=Detail!$H$7,'Cash Flow'!F12+1,0) -> 3 | H12: =+IF(H17>=Detail!$H$7,'Cash Flow'!G12+1,0) -> 4 | I12: =+IF(I17>=Detail!$H$7,'Cash Flow'!H12+1,0) -> 5 | J12: =+IF(J17>=Detail!$H$7,'Cash Flow'!I12+1,0) -> 6 | K12: =+IF(K17>=Detail!$H$7,'Cash Flow'!J12+1,0) -> 7 | L12: =+IF(L17>=Detail!$H$7,'Cash Flow'!K12+1,0) -> 8 | ... FS12: =+IF(FS17>=Detail!$H$7,'Cash Flow'!FR12+1,0) -> 171
E13: =+ROUNDUP(E12/12,0) -> 1 | F13: =+ROUNDUP(F12/12,0) -> 1 | G13: =+ROUNDUP(G12/12,0) -> 1 | H13: =+ROUNDUP(H12/12,0) -> 1 | I13: =+ROUNDUP(I12/12,0) -> 1 | J13: =+ROUNDUP(J12/12,0) -> 1 | K13: =+ROUNDUP(K12/12,0) -> 1 | L13: =+ROUNDUP(L12/12,0) -> 1 | ... FS13: =+ROUNDUP(FS12/12,0) -> 15
B14: Growth Rate:
B15: Growth Rate Timing: Monthly | E15: =+IF(E5<Detail!$M$141,0,'Cash Flow'!D15+1) -> 0 | F15: =+IF(F5<Detail!$M$141,0,'Cash Flow'!E15+1) -> 0 | G15: =+IF(G5<Detail!$M$141,0,'Cash Flow'!F15+1) -> 0 | H15: =+IF(H5<Detail!$M$141,0,'Cash Flow'!G15+1) -> 0 | I15: =+IF(I5<Detail!$M$141,0,'Cash Flow'!H15+1) -> 0 | J15: =+IF(J5<Detail!$M$141,0,'Cash Flow'!I15+1) -> 0 | K15: =+IF(K5<Detail!$M$141,0,'Cash Flow'!J15+1) -> 0 | L15: =+IF(L5<Detail!$M$141,0,'Cash Flow'!K15+1) -> 1 | ... FS15: =+IF(FS5<Detail!$M$141,0,'Cash Flow'!FR15+1) -> 164
B16: Growth Rate Timing: Yearly | E16: =+ROUNDUP(E15/12,0) -> 0 | F16: =+ROUNDUP(F15/12,0) -> 0 | G16: =+ROUNDUP(G15/12,0) -> 0 | H16: =+ROUNDUP(H15/12,0) -> 0 | I16: =+ROUNDUP(I15/12,0) -> 0 | J16: =+ROUNDUP(J15/12,0) -> 0 | K16: =+ROUNDUP(K15/12,0) -> 0 | L16: =+ROUNDUP(L15/12,0) -> 1 | ... FS16: =+ROUNDUP(FS15/12,0) -> 14
B17: Month | E17: 0 | F17: =E17+1 -> 1 | G17: =F17+1 -> 2 | H17: =G17+1 -> 3 | I17: =H17+1 -> 4 | J17: =I17+1 -> 5 | K17: =J17+1 -> 6 | L17: =K17+1 -> 7 | M17: =L17+1 -> 8 | ... FS17: =FR17+1 -> 170 | FT17: Yr 1 Total | FU17: Yr 2 Total | FV17: Yr 3 Total | FW17: Yr 4 Total | FX17: Yr 5 Total
B18: Lease Expirations | E18: =288/12 -> 24 | F18: =288/12 -> 24 | G18: =288/12 -> 24 | H18: =288/12 -> 24 | I18: =288/12 -> 24 | J18: =288/12 -> 24 | K18: =288/12 -> 24 | L18: =288/12 -> 24 | ... P18: =288/12 -> 24 | Q18: 15 | R18: 20 | S18: 25 | T18: 25 | U18: 25 | V18: 25 | W18: 25.040394 | X18: 22.285726 | Y18: 20.597371 | Z18: =M22+M21 -> 24 | AA18: =N22+N21 -> 24 | AB18: =O22+O21 -> 24 | AC18: =P22+P21 -> 24 | AD18: =Q22+Q21 -> 15 | AE18: =R22+R21 -> 20 | AF18: =S22+S21 -> 25 | AG18: =T22+T21 -> 25 | ... FS18: =FF22+FF21 -> 25
B19: Move Outs | C19: 0.4 | E19: =E18*$C$19 -> 9.6 | F19: =F18*$C$19 -> 9.6 | G19: =G18*$C$19 -> 9.6 | H19: =H18*$C$19 -> 9.6 | I19: =I18*$C$19 -> 9.6 | J19: =J18*$C$19 -> 9.6 | K19: =K18*$C$19 -> 9.6 | L19: =L18*$C$19 -> 9.6 | ... FS19: =FS18*$C$19 -> 10
B21: Renewals | E21: =E18-E19 -> 14.4 | F21: =F18-F19 -> 14.4 | G21: =G18-G19 -> 14.4 | H21: =H18-H19 -> 14.4 | I21: =I18-I19 -> 14.4 | J21: =J18-J19 -> 14.4 | K21: =K18-K19 -> 14.4 | L21: =L18-L19 -> 14.4 | ... FS21: =FS18-FS19 -> 15
B22: New Move-ins | E22: =E19 -> 9.6 | F22: =F19 -> 9.6 | G22: =G19 -> 9.6 | H22: =H19 -> 9.6 | I22: =I19 -> 9.6 | J22: =J19 -> 9.6 | K22: =K19 -> 9.6 | L22: =L19 -> 9.6 | ... FS22: =FS19 -> 10
B23: Occupied Units | E23: =Detail!C8*Detail!F34 -> 273.6 | F23: =F22+F21-F18+E23 -> 273.6 | G23: =G22+G21-G18+F23 -> 273.6 | H23: =H22+H21-H18+G23 -> 273.6 | I23: =I22+I21-I18+H23 -> 273.6 | J23: =J22+J21-J18+I23 -> 273.6 | K23: =K22+K21-K18+J23 -> 273.6 | L23: =L22+L21-L18+K23 -> 273.6 | M23: =M22+M21-M18+L23 -> 273.6 | ... FS23: =FS22+FS21-FS18+FR23 -> 273.6
B27: Market Rents | E27: =Detail!$H$67*E125 -> 1910.296 | F27: =Detail!$H$67*F125 -> 1910.296 | G27: =Detail!$H$67*G125 -> 1910.296 | H27: =Detail!$H$67*H125 -> 1910.296 | I27: =Detail!$H$67*I125 -> 1910.296 | J27: =Detail!$H$67*J125 -> 1910.296 | K27: =Detail!$H$67*K125 -> 1910.296 | L27: =Detail!$H$67*L125 -> 1915.0718 | ... FS27: =Detail!$H$67*FS125 -> 2876.9957
B28: Market Rents / SF | E28: =E27/Detail!$F$67 -> 1.8713104 | F28: =F27/Detail!$F$67 -> 1.8713104 | G28: =G27/Detail!$F$67 -> 1.8713104 | H28: =H27/Detail!$F$67 -> 1.8713104 | I28: =I27/Detail!$F$67 -> 1.8713104 | J28: =J27/Detail!$F$67 -> 1.8713104 | K28: =K27/Detail!$F$67 -> 1.8713104 | L28: =L27/Detail!$F$67 -> 1.8759887 | ... FS28: =FS27/Detail!$F$67 -> 2.8182815
B29: In-Place Rent | E29: =(E39+E40)/Detail!$C$8 -> 1887.4315 | F29: =(F39+F40)/Detail!$C$8 -> 1888.1936 | G29: =(G39+G40)/Detail!$C$8 -> 1888.9304 | H29: =(H39+H40)/Detail!$C$8 -> 1889.6425 | I29: =(I39+I40)/Detail!$C$8 -> 1890.331 | J29: =(J39+J40)/Detail!$C$8 -> 1890.9965 | K29: =(K39+K40)/Detail!$C$8 -> 1891.6398 | L29: =(L39+L40)/Detail!$C$8 -> 1892.6597 | ... FS29: =(FS39+FS40)/Detail!$C$8 -> 2854.4328
B30: Average In-Place Rent / SF | E30: =E29/Detail!$F$67 -> 1.8489124 | F30: =+F29/Detail!$F$67 -> 1.849659 | G30: =+G29/Detail!$F$67 -> 1.8503808 | H30: =+H29/Detail!$F$67 -> 1.8510784 | I30: =+I29/Detail!$F$67 -> 1.8517528 | J30: =+J29/Detail!$F$67 -> 1.8524047 | K30: =+K29/Detail!$F$67 -> 1.8530349 | L30: =+L29/Detail!$F$67 -> 1.854034 | M30: =+M29/Detail!$F$67 -> 1.8551566 | ... FS30: =+FS29/Detail!$F$67 -> 2.796179
B31: Occupancy | E31: =1+E41/(E39+E40) -> 0.94939429 | F31: =1+F41/(F39+F40) -> 0.94941472 | G31: =1+G41/(G39+G40) -> 0.94943445 | H31: =1+H41/(H39+H40) -> 0.94945351 | I31: =1+I41/(I39+I40) -> 0.94947192 | J31: =1+J41/(J39+J40) -> 0.9494897 | K31: =1+K41/(K39+K40) -> 0.94950688 | L31: =1+L41/(L39+L40) -> 0.94940792 | ... P31: =1+P41/(P39+P40) -> 0.9490429 | Q31: =Q23/Detail!$D$67 -> 0.95 | R31: =R23/Detail!$D$67 -> 0.95 | S31: =S23/Detail!$D$67 -> 0.95 | T31: =T23/Detail!$D$67 -> 0.95 | U31: =U23/Detail!$D$67 -> 0.95 | V31: =V23/Detail!$D$67 -> 0.95 | W31: =W23/Detail!$D$67 -> 0.95 | X31: =X23/Detail!$D$67 -> 0.95 | ... FS31: =FS23/Detail!$D$67 -> 0.95
B33: In-Place Revenue | E33: =Detail!L67*(1-Detail!F33) -> 522657 | F33: =SUM(E39:E41) -> 516072 | G33: =SUM(F39:F41) -> 516291.5 | H33: =SUM(G39:G41) -> 516503.68 | I33: =SUM(H39:H41) -> 516708.79 | J33: =SUM(I39:I41) -> 516907.06 | K33: =SUM(J39:J41) -> 517098.73 | L33: =SUM(K39:K41) -> 517284 | M33: =SUM(L39:L41) -> 517508.95 | ... FS33: =SUM(FR39:FR41) -> 778553.32
B34: New Leases | E34: 0 | F34: =F27*F22 -> 18338.842 | G34: =G27*G22 -> 18338.842 | H34: =H27*H22 -> 18338.842 | I34: =I27*I22 -> 18338.842 | J34: =J27*J22 -> 18338.842 | K34: =K27*K22 -> 18338.842 | L34: =L27*L22 -> 18384.689 | M34: =M27*M22 -> 18430.651 | ... P34: =P27*P22 -> 18569.227 | Q34: =Q27*(Q22+Q21) -> 29086.953 | R34: =R27*(R22+R21) -> 38879.56 | S34: =S27*(S22+S21) -> 48720.949 | T34: =T27*(T22+T21) -> 48842.751 | U34: =U27*(U22+U21) -> 48964.858 | V34: =V27*(V22+V21) -> 49087.27 | W34: =W27*(W22+W21) -> 49289.499 | X34: =X27*(X22+X21) -> 43976.88 | ... FS34: =FS27*(FS22+FS21) -> 71924.892
B35: Old Leases | E35: =-D29*E19 -> 0 | F35: =-E29*F19 -> -18119.342 | G35: =-F29*G19 -> -18126.659 | H35: =-G29*H19 -> -18133.731 | I35: =-H29*I19 -> -18140.568 | J35: =-I29*J19 -> -18147.178 | K35: =-J29*K19 -> -18153.566 | L35: =-K29*L19 -> -18159.742 | ... P35: =-O29*P19 -> -18206.028 | Q35: =-H29*Q18 -> -28344.638 | R35: =-I29*R18 -> -37806.62 | S35: =-J29*S18 -> -47274.912 | T35: =-K29*T18 -> -47290.995 | U35: =-L29*U18 -> -47316.492 | V35: =-M29*V18 -> -47345.143 | W35: =-N29*W18 -> -47453.403 | X35: =-O29*X18 -> -42264.016 | ... FS35: =-FJ29*FS18 -> -69830.314
B36: Total Rent Collected | E36: =SUM(E33:E35) -> 522657 | F36: =SUM(F33:F35) -> 516291.5 | G36: =SUM(G33:G35) -> 516503.68 | H36: =SUM(H33:H35) -> 516708.79 | I36: =SUM(I33:I35) -> 516907.06 | J36: =SUM(J33:J35) -> 517098.73 | K36: =SUM(K33:K35) -> 517284 | L36: =SUM(L33:L35) -> 517508.95 | ... FS36: =SUM(FS33:FS35) -> 780647.9
B38: Income | D38: 0
B39: Gross Potential Rent | E39: =+Detail!$D$67*'Cash Flow'!E27 -> 550165.26 | F39: =+Detail!$D$67*'Cash Flow'!F27 -> 550165.26 | G39: =+Detail!$D$67*'Cash Flow'!G27 -> 550165.26 | H39: =+Detail!$D$67*'Cash Flow'!H27 -> 550165.26 | I39: =+Detail!$D$67*'Cash Flow'!I27 -> 550165.26 | J39: =+Detail!$D$67*'Cash Flow'!J27 -> 550165.26 | K39: =+Detail!$D$67*'Cash Flow'!K27 -> 550165.26 | L39: =+Detail!$D$67*'Cash Flow'!L27 -> 551540.67 | ... FS39: =+Detail!$D$67*'Cash Flow'!FS27 -> 828574.75 | FT39: =SUMIFS($E39:$FS39,$E$8:$FS$8,FT$5) -> 3851156.8 | FU39: =SUMIFS($E39:$FS39,$E$8:$FS$8,FU$5) -> 6710254.9 | FV39: =SUMIFS($E39:$FS39,$E$8:$FS$8,FV$5) -> 6914353.8 | FW39: =SUMIFS($E39:$FS39,$E$8:$FS$8,FW$5) -> 7124660.5 | FX39: =SUMIFS($E39:$FS39,$E$8:$FS$8,FX$5) -> 7341363.8
B40: Loss to Lease | E40: -6585 | F40: =-(F39-F36+F41) -> -6365.5 | G40: =-(G39-G36+G41) -> -6153.3167 | H40: =-(H39-H36+H41) -> -5948.2061 | I40: =-(I39-I36+I41) -> -5749.9326 | J40: =-(J39-J36+J41) -> -5558.2682 | K40: =-(K39-K36+K41) -> -5372.9925 | L40: =-(L39-L36+L41) -> -6454.6882 | M40: =-(M39-M36+M41) -> -7503.4793 | ... FS40: =-(FS39-FS36+FS41) -> -6498.1173
B41: Vacancy | E41: =-(Detail!$D$67-'Cash Flow'!E23)*'Cash Flow'!E27 -> -27508.263 | F41: =-(Detail!$D$67-'Cash Flow'!F23)*'Cash Flow'!F27 -> -27508.263 | G41: =-(Detail!$D$67-'Cash Flow'!G23)*'Cash Flow'!G27 -> -27508.263 | H41: =-(Detail!$D$67-'Cash Flow'!H23)*'Cash Flow'!H27 -> -27508.263 | I41: =-(Detail!$D$67-'Cash Flow'!I23)*'Cash Flow'!I27 -> -27508.263 | J41: =-(Detail!$D$67-'Cash Flow'!J23)*'Cash Flow'!J27 -> -27508.263 | K41: =-(Detail!$D$67-'Cash Flow'!K23)*'Cash Flow'!K27 -> -27508.263 | L41: =-(Detail!$D$67-'Cash Flow'!L23)*'Cash Flow'!L27 -> -27577.034 | ... FS41: =-(Detail!$D$67-'Cash Flow'!FS23)*'Cash Flow'!FS27 -> -41428.738 | FT41: =SUMIFS($E41:$FS41,$E$8:$FS$8,FT$5) -> -192557.84 | FU41: =SUMIFS($E41:$FS41,$E$8:$FS$8,FU$5) -> -335512.75 | FV41: =SUMIFS($E41:$FS41,$E$8:$FS$8,FV$5) -> -345717.69 | FW41: =SUMIFS($E41:$FS41,$E$8:$FS$8,FW$5) -> -356233.02 | FX41: =SUMIFS($E41:$FS41,$E$8:$FS$8,FX$5) -> -367068.19
B42: Gross Schedued Rent | E42: =SUM(E39:E41) -> 516072 | F42: =SUM(F39:F41) -> 516291.5 | G42: =SUM(G39:G41) -> 516503.68 | H42: =SUM(H39:H41) -> 516708.79 | I42: =SUM(I39:I41) -> 516907.06 | J42: =SUM(J39:J41) -> 517098.73 | K42: =SUM(K39:K41) -> 517284 | L42: =SUM(L39:L41) -> 517508.95 | ... FS42: =SUM(FS39:FS41) -> 780647.9 | FT42: =SUMIFS($E42:$FS42,$E$8:$FS$8,FT$5) -> 3616865.8 | FU42: =SUMIFS($E42:$FS42,$E$8:$FS$8,FU$5) -> 6257155.6 | FV42: =SUMIFS($E42:$FS42,$E$8:$FS$8,FV$5) -> 6486654.9 | FW42: =SUMIFS($E42:$FS42,$E$8:$FS$8,FW$5) -> 6727274.4 | FX42: =SUMIFS($E42:$FS42,$E$8:$FS$8,FX$5) -> 6926597.8
B43: Bad Debt / Credit Loss | E43: =-E42*Detail!$F$36 -> -5160.72 | F43: =-F42*Detail!$F$36 -> -5162.915 | G43: =-G42*Detail!$F$36 -> -5165.0368 | H43: =-H42*Detail!$F$36 -> -5167.0879 | I43: =-I42*Detail!$F$36 -> -5169.0706 | J43: =-J42*Detail!$F$36 -> -5170.9873 | K43: =-K42*Detail!$F$36 -> -5172.84 | L43: =-L42*Detail!$F$36 -> -5175.0895 | ... FS43: =-FS42*Detail!$F$36 -> -7806.479 | FT43: =SUMIFS($E43:$FS43,$E$8:$FS$8,FT$5) -> -36168.658 | FU43: =SUMIFS($E43:$FS43,$E$8:$FS$8,FU$5) -> -62571.556 | FV43: =SUMIFS($E43:$FS43,$E$8:$FS$8,FV$5) -> -64866.549 | FW43: =SUMIFS($E43:$FS43,$E$8:$FS$8,FW$5) -> -67272.744 | FX43: =SUMIFS($E43:$FS43,$E$8:$FS$8,FX$5) -> -69265.978
B44: Concessions | E44: =-E22*E27*1.5 -> -27508.263 | F44: =-F22*F27*1.5 -> -27508.263 | G44: =-G22*G27*1.5 -> -27508.263 | H44: =-H22*H27*2 -> -36677.684 | I44: =-I22*I27*2 -> -36677.684 | J44: =-J22*J27*2 -> -36677.684 | K44: =-K22*K27*2 -> -36677.684 | L44: =-L22*L27*2 -> -36769.378 | M44: =-M22*M27*2 -> -36861.302 | N44: =-N22*N27*2 -> -36953.455 | O44: =-O22*O27*2 -> -37045.839 | P44: =-P22*P27*2 -> -37138.453 | Q44: =-Q22*Q27*1.5 -> -17452.172 | R44: =-R22*R27*1.5 -> -23327.736 | S44: =-S22*S27*1.5 -> -29232.569 | T44: =-T22*T27*1.5 -> -29305.651 | U44: =-U22*U27*1 -> -19585.943 | V44: =-V22*V27*1 -> -19634.908 | W44: =-W22*W27*1 -> -19715.8 | X44: 0 | Y44: =IF(Y31>=95%,0,(-Y27*$FZ$44)*Y22) -> 0 | Z44: =IF(Z31>=95%,0,(-Z27*$FZ$44)*Z22) -> 0 | AA44: =IF(AA31>=95%,0,(-AA27*$FZ$44)*AA22) -> 0 | AB44: =IF(AB31>=95%,0,(-AB27*$FZ$44)*AB22) -> 0 | AC44: =IF(AC31>=95%,0,(-AC27*$FZ$44)*AC22) -> 0 | AD44: =IF(AD31>=95%,0,(-AD27*$FZ$44)*AD22) -> 0 | AE44: =IF(AE31>=95%,0,(-AE27*$FZ$44)*AE22) -> 0 | AF44: =IF(AF31>=95%,0,(-AF27*$FZ$44)*AF22) -> 0 | ... FS44: =IF(FS31>=95%,0,(-FS27*$FZ$44)*FS22) -> 0 | FT44: =SUMIFS($E44:$FS44,$E$8:$FS$8,FT$5) -> -229235.53 | FU44: =SUMIFS($E44:$FS44,$E$8:$FS$8,FU$5) -> -343023.2 | FV44: =SUMIFS($E44:$FS44,$E$8:$FS$8,FV$5) -> 0 | FW44: =SUMIFS($E44:$FS44,$E$8:$FS$8,FW$5) -> 0 | FX44: =SUMIFS($E44:$FS44,$E$8:$FS$8,FX$5) -> 0 | FZ44: 2 | GA44: Concessions / month
B45: Total Collected Rent | E45: =SUM(E42:E44) -> 483403.01 | F45: =SUM(F42:F44) -> 483620.32 | G45: =SUM(G42:G44) -> 483830.38 | H45: =SUM(H42:H44) -> 474864.02 | I45: =SUM(I42:I44) -> 475060.31 | J45: =SUM(J42:J44) -> 475250.06 | K45: =SUM(K42:K44) -> 475433.48 | L45: =SUM(L42:L44) -> 475564.48 | ... FS45: =SUM(FS42:FS44) -> 772841.42 | FT45: =SUMIFS($E45:$FS45,$E$8:$FS$8,FT$5) -> 3351461.6 | FU45: =SUMIFS($E45:$FS45,$E$8:$FS$8,FU$5) -> 5851560.8 | FV45: =SUMIFS($E45:$FS45,$E$8:$FS$8,FV$5) -> 6421788.4 | FW45: =SUMIFS($E45:$FS45,$E$8:$FS$8,FW$5) -> 6660001.7 | FX45: =SUMIFS($E45:$FS45,$E$8:$FS$8,FX$5) -> 6857331.8
B46: Commercial Income | E46: 0 | F46: 0 | G46: 0 | H46: 0 | I46: 0 | J46: 0 | K46: 0 | L46: 0 | M46: 0 | N46: 0 | O46: 0 | P46: 0 | Q46: 0 | R46: 0 | S46: 0 | T46: 0 | U46: 0 | V46: 0 | W46: 0 | X46: 0 | Y46: 0 | Z46: 0 | AA46: 0 | AB46: 0 | AC46: 0 | AD46: 0 | AE46: 0 | AF46: 0 | AG46: 0 | AH46: 0 | AI46: 0 | AJ46: 0 | AK46: 0 | AL46: 0 | AM46: 0 | AN46: 0 | AO46: 0 | AP46: 0 | AQ46: 0 | AR46: 0 | AS46: 0 | AT46: 0 | AU46: 0 | AV46: 0 | AW46: 0 | AX46: 0 | AY46: 0 | AZ46: 0 | BA46: 0 | BB46: 0 | BC46: 0 | BD46: 0 | BE46: 0 | BF46: 0 | BG46: 0 | BH46: 0 | BI46: 0 | BJ46: 0 | BK46: 0 | BL46: 0 | BM46: 0 | BN46: 0 | BO46: 0 | BP46: 0 | BQ46: 0 | BR46: 0 | BS46: 0 | BT46: 0 | BU46: 0 | BV46: 0 | BW46: 0 | BX46: 0 | BY46: 0 | BZ46: 0 | CA46: 0 | CB46: 0 | CC46: 0 | CD46: 0 | CE46: 0 | CF46: 0 | CG46: 0 | CH46: 0 | CI46: 0 | CJ46: 0 | CK46: 0 | CL46: 0 | CM46: 0 | CN46: 0 | CO46: 0 | CP46: 0 | CQ46: 0 | CR46: 0 | CS46: 0 | CT46: 0 | CU46: 0 | CV46: 0 | CW46: 0 | CX46: 0 | CY46: 0 | CZ46: 0 | DA46: 0 | DB46: 0 | DC46: 0 | DD46: 0 | DE46: 0 | DF46: 0 | DG46: 0 | DH46: 0 | DI46: 0 | DJ46: 0 | DK46: 0 | DL46: 0 | DM46: 0 | DN46: 0 | DO46: 0 | DP46: 0 | DQ46: 0 | DR46: 0 | DS46: 0 | DT46: 0 | DU46: 0 | DV46: 0 | DW46: 0 | DX46: 0 | DY46: 0 | DZ46: 0 | EA46: 0 | EB46: 0 | EC46: 0 | ED46: 0 | EE46: 0 | EF46: 0 | EG46: 0 | EH46: 0 | EI46: 0 | EJ46: 0 | EK46: 0 | EL46: 0 | EM46: 0 | EN46: 0 | EO46: 0 | EP46: 0 | EQ46: 0 | ER46: 0 | ES46: 0 | ET46: 0 | EU46: 0 | EV46: 0 | EW46: 0 | EX46: 0 | EY46: 0 | EZ46: 0 | FA46: 0 | FB46: 0 | FC46: 0 | FD46: 0 | FE46: 0 | FF46: 0 | FG46: 0 | FH46: 0 | FI46: 0 | FJ46: 0 | FK46: 0 | FL46: 0 | FM46: 0 | FN46: 0 | FO46: 0 | FP46: 0 | FQ46: 0 | FR46: 0 | FS46: 0 | FT46: =SUMIFS($E46:$FS46,$E$8:$FS$8,FT$5) -> 0 | FU46: =SUMIFS($E46:$FS46,$E$8:$FS$8,FU$5) -> 0 | FV46: =SUMIFS($E46:$FS46,$E$8:$FS$8,FV$5) -> 0 | FW46: =SUMIFS($E46:$FS46,$E$8:$FS$8,FW$5) -> 0 | FX46: =SUMIFS($E46:$FS46,$E$8:$FS$8,FX$5) -> 0
FT47: =SUMIFS($E47:$FS47,$E$8:$FS$8,FT$5) -> 0 | FU47: =SUMIFS($E47:$FS47,$E$8:$FS$8,FU$5) -> 0 | FV47: =SUMIFS($E47:$FS47,$E$8:$FS$8,FV$5) -> 0 | FW47: =SUMIFS($E47:$FS47,$E$8:$FS$8,FW$5) -> 0 | FX47: =SUMIFS($E47:$FS47,$E$8:$FS$8,FX$5) -> 0
...

Sheet Sensitivity
B2: LEVERED PROJECT IRR & MULTIPLE SENSITIVITY
D4: ANNUAL RENT GROWTH
C5: =TEXT('Cash Flow'!C120,"0.0%")&" / "&TEXT('Cash Flow'!C121,"0.00")&"x" -> 25.5% / 2.32x | D5: =E5-0.5% -> 0.015 | E5: =F5-0.5% -> 0.02 | F5: =G5-0.5% -> 0.025 | G5: 0.03 | H5: =G5+0.5% -> 0.035 | I5: =H5+0.5% -> 0.04 | M5: Rent Growth | N5: 0.03
B6: ANNUAL EXPENSE GROWTH | C6: =C7-0.5% -> 0.01 | D6: 21.1% / 2.03x | E6: 23.1% / 2.17x | F6: 25.1% / 2.30x | G6: 27.0% / 2.43x | H6: 28.8% / 2.57x | I6: 30.6% / 2.71x | M6: Expense Growth | N6: 0.02
C7: =C8-0.5% -> 0.015 | D7: 20.3% / 1.98x | E7: 22.3% / 2.11x | F7: 24.3% / 2.24x | G7: 26.2% / 2.38x | H7: 28.1% / 2.51x | I7: 29.9% / 2.65x
C8: 0.02 | D8: 19.4% / 1.93x | E8: 21.5% / 2.06x | F8: 23.5% / 2.19x | G8: 25.5% / 2.32x | H8: 27.4% / 2.46x | I8: 29.2% / 2.60x
C9: =C8+0.5% -> 0.025 | D9: 18.5% / 1.87x | E9: 20.6% / 2.00x | F9: 22.7% / 2.14x | G9: 24.7% / 2.27x | H9: 26.6% / 2.41x | I9: 28.5% / 2.54x
C10: =C9+0.5% -> 0.03 | D10: 17.5% / 1.82x | E10: 19.7% / 1.95x | F10: 21.8% / 2.08x | G10: 23.8% / 2.21x | H10: 25.8% / 2.35x | I10: 27.7% / 2.49x
C11: =C10+0.5% -> 0.035 | D11: 16.5% / 1.76x | E11: 18.7% / 1.89x | F11: 20.9% / 2.02x | G11: 23.0% / 2.16x | H11: 25.0% / 2.29x | I11: 26.9% / 2.43x

Sheet Waterfall (Two Tier)
B2: Sentosa Recap
B3: Waterfall Analysis
B4: Equity Capitalization
B5: LP Equity | C5: =E5/$E$7 -> 0.68265386 | E5: =Summary!C14 -> 12922000
B6: GP Equity | C6: =1-C5 -> 0.31734614 | E6: =E7-E5 -> 6007066.2
B7: Total | C7: =SUM(C5:C6) -> 1 | E7: =Summary!C15 -> 18929066
B9: Promote Structure | E9: Sponsor
C10: Hurdle | E10: Promote
B11: Tier I | C11: -- | E11: 0
B12: Tier II (after) | C12: 0.08 | E12: 0.2
B13: Tier III (after) | C13: 0.11 | E13: 0.25
B14: Tier III (after) | C14: 0.17 | E14: 0.35
B16: Monthly Cash Flow | I16: =YEAR(I17) -> 2026 | J16: =YEAR(J17) -> 2026 | K16: =YEAR(K17) -> 2026 | L16: =YEAR(L17) -> 2026 | M16: =YEAR(M17) -> 2026 | N16: =YEAR(N17) -> 2026 | O16: =YEAR(O17) -> 2026 | P16: =YEAR(P17) -> 2027 | ... FB16: =YEAR(FB17) -> 2038
G17: TOTAL | I17: ='Cash Flow'!E5 -> 46203 | J17: =EDATE(I17, 1) -> 46233 | K17: =EDATE(J17, 1) -> 46264 | L17: =EDATE(K17, 1) -> 46295 | M17: =EDATE(L17, 1) -> 46325 | N17: =EDATE(M17, 1) -> 46356 | O17: =EDATE(N17, 1) -> 46386 | P17: =EDATE(O17, 1) -> 46417 | Q17: =EDATE(P17, 1) -> 46446 | ... FB17: =EDATE(FA17, 1) -> 50737 | FD17: TOTAL
B18: ='Cash Flow'!B112 -> Equity Contribution | I18: ='Cash Flow'!E112 -> -18929066 | J18: ='Cash Flow'!F112 -> 0 | K18: ='Cash Flow'!G112 -> 0 | L18: ='Cash Flow'!H112 -> 0 | M18: ='Cash Flow'!I112 -> 0 | N18: ='Cash Flow'!J112 -> 0 | O18: ='Cash Flow'!K112 -> 0 | P18: ='Cash Flow'!L112 -> 0 | ... FB18: ='Cash Flow'!EX112 -> 0 | FD18: =+SUM(I18:FB18) -> -18929066
B19: ='Cash Flow'!B113 -> Acquisition Loan Repayment | I19: ='Cash Flow'!E113 -> 0 | J19: ='Cash Flow'!F113 -> 0 | K19: ='Cash Flow'!G113 -> 0 | L19: ='Cash Flow'!H113 -> 0 | M19: ='Cash Flow'!I113 -> 0 | N19: ='Cash Flow'!J113 -> 0 | O19: ='Cash Flow'!K113 -> 0 | P19: ='Cash Flow'!L113 -> 0 | ... FB19: ='Cash Flow'!EX113 -> 0 | FD19: =+SUM(I19:FB19) -> -52100000
B20: ='Cash Flow'!B114 -> Permanent Loan Infusion | I20: ='Cash Flow'!E114 -> 0 | J20: ='Cash Flow'!F114 -> 0 | K20: ='Cash Flow'!G114 -> 0 | L20: ='Cash Flow'!H114 -> 0 | M20: ='Cash Flow'!I114 -> 0 | N20: ='Cash Flow'!J114 -> 0 | O20: ='Cash Flow'!K114 -> 0 | P20: ='Cash Flow'!L114 -> 0 | ... FB20: ='Cash Flow'!EX114 -> 0 | FD20: =+SUM(I20:FB20) -> 0
B21: ='Cash Flow'!B115 -> Net Sale Proceeds | I21: ='Cash Flow'!E115 -> 0 | J21: ='Cash Flow'!F115 -> 0 | K21: ='Cash Flow'!G115 -> 0 | L21: ='Cash Flow'!H115 -> 0 | M21: ='Cash Flow'!I115 -> 0 | N21: ='Cash Flow'!J115 -> 0 | O21: ='Cash Flow'!K115 -> 0 | P21: ='Cash Flow'!L115 -> 0 | ... FB21: ='Cash Flow'!EX115 -> 0 | FD21: =+SUM(I21:FB21) -> 91571646
B22: ='Cash Flow'!B116 -> Permanent Loan Repayment | I22: ='Cash Flow'!E116 -> 0 | J22: ='Cash Flow'!F116 -> 0 | K22: ='Cash Flow'!G116 -> 0 | L22: ='Cash Flow'!H116 -> 0 | M22: ='Cash Flow'!I116 -> 0 | N22: ='Cash Flow'!J116 -> 0 | O22: ='Cash Flow'!K116 -> 0 | P22: ='Cash Flow'!L116 -> 0 | ... FB22: ='Cash Flow'!EX116 -> 0 | FD22: =+SUM(I22:FB22) -> 0
B23: ='Cash Flow'!B117 -> CF After Debt Service | I23: ='Cash Flow'!E117 -> 60358.09 | J23: ='Cash Flow'!F117 -> 52248.378 | K23: ='Cash Flow'!G117 -> 52453.133 | L23: ='Cash Flow'!H117 -> 52055.327 | M23: ='Cash Flow'!I117 -> 43925.131 | N23: ='Cash Flow'!J117 -> 52431.612 | O23: ='Cash Flow'!K117 -> 44288.871 | P23: ='Cash Flow'!L117 -> 44150.746 | ... FB23: ='Cash Flow'!EX117 -> 0 | FD23: =+SUM(I23:FB23) -> 4450230.3
I24: 0 | J24: 0 | K24: 0 | L24: 0 | M24: 0 | N24: 0 | O24: 0 | P24: 0 | Q24: 0 | R24: 0 | S24: 0 | T24: 0 | U24: 0 | V24: 0 | W24: 0 | X24: 0 | Y24: 0 | Z24: 0 | AA24: 0 | AB24: 0 | AC24: 0 | AD24: 0 | AE24: 0 | AF24: 0 | AG24: 0 | AH24: 0 | AI24: 0 | AJ24: 0 | AK24: 0 | AL24: 0 | AM24: 0 | AN24: 0 | AO24: 0 | AP24: 0 | AQ24: 0 | AR24: 0 | AS24: 0 | AT24: 0 | AU24: 0 | AV24: 0 | AW24: 0 | AX24: 0 | AY24: 0 | AZ24: 0 | BA24: 0 | BB24: 0 | BC24: 0 | BD24: 0 | BE24: 0 | BF24: 0 | BG24: 0 | BH24: 0 | BI24: 0 | BJ24: 0 | BK24: 0 | BL24: 0 | BM24: 0 | BN24: 0 | BO24: 0 | BP24: 0 | BQ24: 0 | BR24: 0 | BS24: 0 | BT24: 0 | BU24: 0 | BV24: 0 | BW24: 0 | BX24: 0 | BY24: 0 | BZ24: 0 | CA24: 0 | CB24: 0 | CC24: 0 | CD24: 0 | CE24: 0 | CF24: 0 | CG24: 0 | CH24: 0 | CI24: 0 | CJ24: 0 | CK24: 0 | CL24: 0 | CM24: 0 | CN24: 0 | CO24: 0 | CP24: 0 | CQ24: 0 | CR24: 0 | CS24: 0 | CT24: 0 | CU24: 0 | CV24: 0 | CW24: 0 | CX24: 0 | CY24: 0 | CZ24: 0 | DA24: 0 | DB24: 0 | DC24: 0 | DD24: 0 | DE24: 0 | DF24: 0 | DG24: 0 | DH24: 0 | DI24: 0 | DJ24: 0 | DK24: 0 | DL24: 0 | DM24: 0 | DN24: 0 | DO24: 0 | DP24: 0 | DQ24: 0 | DR24: 0 | DS24: 0 | DT24: 0 | DU24: 0 | DV24: 0 | DW24: 0 | DX24: 0 | DY24: 0 | DZ24: 0 | EA24: 0 | EB24: 0 | EC24: 0 | ED24: 0 | EE24: 0 | EF24: 0 | EG24: 0 | EH24: 0 | EI24: 0 | EJ24: 0 | EK24: 0 | EL24: 0 | EM24: 0 | EN24: 0 | EO24: 0 | EP24: 0 | EQ24: 0 | ER24: 0 | ES24: 0 | ET24: 0 | EU24: 0 | EV24: 0 | EW24: 0 | EX24: 0 | EY24: 0 | EZ24: 0 | FA24: 0 | FB24: 0 | FD24: =+SUM(I24:FB24) -> 0
